Workbook

Sheet 피그테일 참고사항
B2: ■ 피그테일 발주참고사항
B4: 구분 | C4: 품목코드 | D4: 품목명 | E4: 수량 | F4: 구분 | G4: ※ 동일한 커넥터 ,모드, 두께, 케이블 색상인 경우 호환 가능하여 발주 시 발주수량 조정 必 ex) 14-P-041 12C 1EA = 14-P-102 1C 12EA 예외 : SK성단용(호환불가) ※ 규격에 별도로 색상이 기입되어 있지 않은 경우 노란색 케이블임 ※ 규격에 n색이 기입되어 있는 경우 호환불가 ex) 6색, 12색 등
B5: 1 | C5: 14-P-041 | D5: PIGTAIL-FC/PC-SM-12C (0.9mm) | E5: 1 | F5: 1
B6: 1 | C6: 14-P-102 | D6: PIGTAIL-FC/PC-SM-1C (0.9mm) | E6: 12 | F6: 1
B7: 2 | C7: 14-P-045 | D7: PIGTAIL-LC/APC-SM-12C (O.9mm) | E7: 1 | F7: 2
B8: 2 | C8: 14-P-076 | D8: PIGTAIL-LC/APC-SM-1C (0.9mm) | E8: 12 | F8: 2
B9: 3 | C9: 14-P-036 | D9: PIGTAIL-LC/PC-SM-12C (0.9mm) | E9: 1 | F9: 3
B10: 3 | C10: 14-P-006 | D10: PIGTAIL-LC/PC-SM-1C (0.9mm) | E10: 12 | F10: 3
B11: 3 | C11: 14-P-086 | D11: PIGTAIL-LC/PC-SM-2C (0.9mm) | E11: 6 | F11: 3
B12: 3 | C12: 14-P-080 | D12: PIGTAIL-LC/PC-SM-4C (0.9mm) | E12: 3 | F12: 3
B13: 4 | C13: 14-P-037 | D13: PIGTAIL-LC/PC-MM-12C (0.9mm) | E13: 1 | F13: 4
B14: 4 | C14: 14-P-003 | D14: PIGTAIL-LC/PC-MM-1C (0.9mm) | E14: 12 | F14: 4
B15: 5 | C15: 14-P-031 | D15: PIGTAIL-SC/APC-SM-12C (0.9mm) | E15: 1 | F15: 5
B16: 5 | C16: 14-P-073 | D16: PIGTAIL-SC/APC-SM-2C (0.9mm) | E16: 6 | F16: 5
... B26: 8 | C26: 14-P-040 | D26: PIGTAIL-SC/PC-SM-4C (0.9mm) | E26: 3 | F26: 8

Sheet 발주검토
I2: 월 평균판매량 | P2: =재고현황!#REF! -> #REF!
A3: 판매금액(2개년) | B3: 순번 | C3: 품목코드 | D3: 품목명 | E3: 규격 | F3: 요약 | G3: 최다판매연월 | H3: 최다 월판매수량 | I3: 24-25년 | J3: 26년 | K3: 전년 판매량 대비 | L3: 판매추이 | M3: 수입구매처 | N3: 리드타임 | O3: 안전재고 | P3: 재고현황 | Q3: 현 가용재고(월) | R3: 입고예정수량 | S3: 입고예정수량 포함 가용재고(월) | T3: 발주예정량 | U3: 입고 후 예상기간 (월)
A4: 2 | B4: 1 | C4: 14-K-362 | D4: OJC-A1-SC/SC-SM-3-PC/PC-SP | E4: K9088996 | F4: =VLOOKUP(C4,'판매현황-통합'!$J$2:$M$1479,4,0) -> 91014 | G4: =VLOOKUP(C4,'판매현황-통합'!J:P,6,0) -> 2025/12 | H4: =VLOOKUP(C4,'판매현황-통합'!J:P,7,0) -> 32271 | I4: =+F4/24 -> 3792.25 | J4: =SUMIF(판매현황_2026!C:C,발주검토!C4,판매현황_2026!F:F)/4 -> 1072.5 | K4: =+J4-I4 -> -2719.75 | L4: =IF(K4<0,"감소","증가") -> 감소 | M4: =VLOOKUP(C4,'판매현황-통합'!$J$1:$Q$1420,8,0) -> Fiberwit Link Communication Co.,LTD | N4: =VLOOKUP(M4,리드타임!$B$3:$D$10,3,0) -> 60 | O4: =I4*3 -> 11376.75 | P4: =IFERROR(VLOOKUP(C4,재고현황!$A:$D,4,0),0) -> 15293 | Q4: =+P4/I4 -> 4.0326983 | R4: =SUMIF(입고예정_260527!C:C,발주검토!C4,입고예정_260527!F:F) -> 20000 | S4: =+(R4+P4)/O4 -> 3.1022041 | U4: =+(+T4+P4+R4-(I4*3))/I4 -> 6.3066122 | V4: A14-SB-N148
A5: 5 | B5: 2 | C5: A14-SB-N261 | D5: SOJC-SM-SC/PC-SC/PC | E5: 908041391, 1M, B3, 3.0mm | F5: =VLOOKUP(C5,'판매현황-통합'!$J$2:$M$1479,4,0) -> 94359 | G5: =VLOOKUP(C5,'판매현황-통합'!J:P,6,0) -> 2024/01 | H5: =VLOOKUP(C5,'판매현황-통합'!J:P,7,0) -> 10760 | I5: =+F5/24 -> 3931.625 | J5: =SUMIF(판매현황_2026!C:C,발주검토!C5,판매현황_2026!F:F)/4 -> 4687.5 | K5: =+J5-I5 -> 755.875 | L5: =IF(K5<0,"감소","증가") -> 증가 | M5: =VLOOKUP(C5,'판매현황-통합'!$J$1:$Q$1420,8,0) -> Fiberwit Link Communication Co.,LTD | N5: =VLOOKUP(M5,리드타임!$B$3:$D$10,3,0) -> 60 | O5: =I5*3 -> 11794.875 | P5: =IFERROR(VLOOKUP(C5,재고현황!$A:$D,4,0),0) -> -90 | Q5: =+P5/I5 -> -0.022891298 | R5: =SUMIF(입고예정_260527!C:C,발주검토!C5,입고예정_260527!F:F) -> 8200 | S5: =+(R5+P5)/O5 -> 0.68758677 | T5: 28000 | U5: =+(+T5+P5+R5-(I5*3))/I5 -> 6.1844975 | V5: A14-SB-N139
A6: 6 | B6: 3 | C6: A14-SB-N268 | D6: SOJC-SM-SC/PC-SC/PC | E6: 908041390, 3M, B3, 3.0mm | F6: =VLOOKUP(C6,'판매현황-통합'!$J$2:$M$1479,4,0) -> 75287 | G6: =VLOOKUP(C6,'판매현황-통합'!J:P,6,0) -> 2024/01 | H6: =VLOOKUP(C6,'판매현황-통합'!J:P,7,0) -> 6792 | I6: =+F6/24 -> 3136.9583 | J6: =SUMIF(판매현황_2026!C:C,발주검토!C6,판매현황_2026!F:F)/4 -> 3795 | K6: =+J6-I6 -> 658.04167 | L6: =IF(K6<0,"감소","증가") -> 증가 | M6: =VLOOKUP(C6,'판매현황-통합'!$J$1:$Q$1420,8,0) -> Fiberwit Link Communication Co.,LTD | N6: =VLOOKUP(M6,리드타임!$B$3:$D$10,3,0) -> 60 | O6: =I6*3 -> 9410.875 | P6: =IFERROR(VLOOKUP(C6,재고현황!$A:$D,4,0),0) -> 4723 | Q6: =+P6/I6 -> 1.5055986 | R6: =SUMIF(입고예정_260527!C:C,발주검토!C6,입고예정_260527!F:F) -> 4010 | S6: =+(R6+P6)/O6 -> 0.92796897 | T6: 20000 | U6: =+(+T6+P6+R6-(I6*3))/I6 -> 6.1595096 | V6: A14-DB-N471
A7: 9 | B7: 4 | C7: 14-K-851 | D7: OJC-A1-SC/SC-SM-3-PC/PC-SP | E7: K9088996_포앤티 | F7: =VLOOKUP(C7,'판매현황-통합'!$J$2:$M$1479,4,0) -> 31318 | G7: =VLOOKUP(C7,'판매현황-통합'!J:P,6,0) -> 2025/12 | H7: =VLOOKUP(C7,'판매현황-통합'!J:P,7,0) -> 7100 | I7: =+F7/24 -> 1304.9167 | J7: =SUMIF(판매현황_2026!C:C,발주검토!C7,판매현황_2026!F:F)/4 -> 0 | K7: =+J7-I7 -> -1304.9167 | L7: =IF(K7<0,"감소","증가") -> 감소 | M7: =VLOOKUP(C7,'판매현황-통합'!$J$1:$Q$1420,8,0) -> Fiberwit Link Communication Co.,LTD | N7: =VLOOKUP(M7,리드타임!$B$3:$D$10,3,0) -> 60 | O7: =I7*3 -> 3914.75 | P7: =IFERROR(VLOOKUP(C7,재고현황!$A:$D,4,0),0) -> 5505 | Q7: =+P7/I7 -> 4.2186602 | R7: =SUMIF(입고예정_260527!C:C,발주검토!C7,입고예정_260527!F:F) -> 0 | S7: =+(R7+P7)/O7 -> 1.4062201 | U7: =+(+T7+P7+R7-(I7*3))/I7 -> 1.2186602 | V7: A14-DB-N455
A8: 17 | B8: 5 | C8: 14-P-018 | D8: PIGTAIL-SC/PC-SM-1C (0.9mm) | E8: 1.5M | F8: =VLOOKUP(C8,'판매현황-통합'!$J$2:$M$1479,4,0) -> 36641 | G8: =VLOOKUP(C8,'판매현황-통합'!J:P,6,0) -> 2026/01 | H8: =VLOOKUP(C8,'판매현황-통합'!J:P,7,0) -> 11550 | I8: =+F8/24 -> 1526.7083 | J8: =SUMIF(판매현황_2026!C:C,발주검토!C8,판매현황_2026!F:F)/4 -> 2957.5 | K8: =+J8-I8 -> 1430.7917 | L8: =IF(K8<0,"감소","증가") -> 증가 | M8: =VLOOKUP(C8,'판매현황-통합'!$J$1:$Q$1420,8,0) -> Fiberwit Link Communication Co.,LTD | N8: =VLOOKUP(M8,리드타임!$B$3:$D$10,3,0) -> 60 | O8: =I8*3 -> 4580.125 | P8: =IFERROR(VLOOKUP(C8,재고현황!$A:$D,4,0),0) -> 4 | Q8: =+P8/I8 -> 0.0026200158 | R8: =SUMIF(입고예정_260527!C:C,발주검토!C8,입고예정_260527!F:F) -> 0 | S8: =+(R8+P8)/O8 -> 0.00087333861 | T8: 14000 | U8: =+(+T8+P8+R8-(I8*3))/I8 -> 6.1726754 | V8: A14-SB-N099
A9: 4 | B9: 6 | C9: A14-DB-N223 | D9: DOJC-SM-LC/PC-LC/PC | E9: 908041006, 10M, B3, 2.0mm | F9: =VLOOKUP(C9,'판매현황-통합'!$J$2:$M$1479,4,0) -> 24439 | G9: =VLOOKUP(C9,'판매현황-통합'!J:P,6,0) -> 2024/04 | H9: =VLOOKUP(C9,'판매현황-통합'!J:P,7,0) -> 2197 | I9: =+F9/24 -> 1018.2917 | J9: =SUMIF(판매현황_2026!C:C,발주검토!C9,판매현황_2026!F:F)/4 -> 761 | K9: =+J9-I9 -> -257.29167 | L9: =IF(K9<0,"감소","증가") -> 감소 | M9: =VLOOKUP(C9,'판매현황-통합'!$J$1:$Q$1420,8,0) -> Fiberwit Link Communication Co.,LTD | N9: =VLOOKUP(M9,리드타임!$B$3:$D$10,3,0) -> 60 | O9: =I9*3 -> 3054.875 | P9: =IFERROR(VLOOKUP(C9,재고현황!$A:$D,4,0),0) -> 2272 | Q9: =+P9/I9 -> 2.2311879 | R9: =SUMIF(입고예정_260527!C:C,발주검토!C9,입고예정_260527!F:F) -> 3900 | S9: =+(R9+P9)/O9 -> 2.0203773 | T9: 3000 | U9: =+(+T9+P9+R9-(I9*3))/I9 -> 6.0072425 | V9: A14-SB-N104
A10: 3 | B10: 7 | C10: A14-DB-N228 | D10: DOJC-SM-LC/PC-LC/PC | E10: 908040697, 15M, B3, 2.0mm | F10: =VLOOKUP(C10,'판매현황-통합'!$J$2:$M$1479,4,0) -> 22527 | G10: =VLOOKUP(C10,'판매현황-통합'!J:P,6,0) -> 2024/04 | H10: =VLOOKUP(C10,'판매현황-통합'!J:P,7,0) -> 1525 | I10: =+F10/24 -> 938.625 | J10: =SUMIF(판매현황_2026!C:C,발주검토!C10,판매현황_2026!F:F)/4 -> 851 | K10: =+J10-I10 -> -87.625 | L10: =IF(K10<0,"감소","증가") -> 감소 | M10: =VLOOKUP(C10,'판매현황-통합'!$J$1:$Q$1420,8,0) -> Fiberwit Link Communication Co.,LTD | N10: =VLOOKUP(M10,리드타임!$B$3:$D$10,3,0) -> 60 | O10: =I10*3 -> 2815.875 | P10: =IFERROR(VLOOKUP(C10,재고현황!$A:$D,4,0),0) -> 2330 | Q10: =+P10/I10 -> 2.4823545 | R10: =SUMIF(입고예정_260527!C:C,발주검토!C10,입고예정_260527!F:F) -> 2600 | S10: =+(R10+P10)/O10 -> 1.7507879 | T10: 3500 | U10: =+(+T10+P10+R10-(I10*3))/I10 -> 5.9812225 | V10: A14-DB-N226
A11: 27 | B11: 8 | C11: A14-SB-N249 | D11: SOJC-SM-SC/PC-SC/APC | E11: 908041420, 3M, B3, 3.0mm | F11: =VLOOKUP(C11,'판매현황-통합'!$J$2:$M$1479,4,0) -> 23336 | G11: =VLOOKUP(C11,'판매현황-통합'!J:P,6,0) -> 2026/02 | H11: =VLOOKUP(C11,'판매현황-통합'!J:P,7,0) -> 4200 | I11: =+F11/24 -> 972.33333 | J11: =SUMIF(판매현황_2026!C:C,발주검토!C11,판매현황_2026!F:F)/4 -> 2360 | K11: =+J11-I11 -> 1387.6667 | L11: =IF(K11<0,"감소","증가") -> 증가 | M11: =VLOOKUP(C11,'판매현황-통합'!$J$1:$Q$1420,8,0) -> Fiberwit Link Communication Co.,LTD | N11: =VLOOKUP(M11,리드타임!$B$3:$D$10,3,0) -> 60 | O11: =I11*3 -> 2917 | P11: =IFERROR(VLOOKUP(C11,재고현황!$A:$D,4,0),0) -> -500 | Q11: =+P11/I11 -> -0.51422695 | R11: =SUMIF(입고예정_260527!C:C,발주검토!C11,입고예정_260527!F:F) -> 8000 | S11: =+(R11+P11)/O11 -> 2.5711347 | T11: 1300 | U11: =+(+T11+P11+R11-(I11*3))/I11 -> 6.0503942 | V11: A14-DB-N307
A12: 25 | B12: 9 | C12: 14-K-357 | D12: OJC-A1-SC/SC-SM-3-APC/APC-SP | E12: K9089111 | F12: =VLOOKUP(C12,'판매현황-통합'!$J$2:$M$1479,4,0) -> 13006 | G12: =VLOOKUP(C12,'판매현황-통합'!J:P,6,0) -> 2024/12 | H12: =VLOOKUP(C12,'판매현황-통합'!J:P,7,0) -> 3000 | I12: =+F12/24 -> 541.91667 | J12: =SUMIF(판매현황_2026!C:C,발주검토!C12,판매현황_2026!F:F)/4 -> 85 | K12: =+J12-I12 -> -456.91667 | L12: =IF(K12<0,"감소","증가") -> 감소 | M12: =VLOOKUP(C12,'판매현황-통합'!$J$1:$Q$1420,8,0) -> Fiberwit Link Communication Co.,LTD | N12: =VLOOKUP(M12,리드타임!$B$3:$D$10,3,0) -> 60 | O12: =I12*3 -> 1625.75 | P12: =IFERROR(VLOOKUP(C12,재고현황!$A:$D,4,0),0) -> 2748 | Q12: =+P12/I12 -> 5.0708904 | R12: =SUMIF(입고예정_260527!C:C,발주검토!C12,입고예정_260527!F:F) -> 1100 | S12: =+(R12+P12)/O12 -> 2.3669076 | T12: 1000 | U12: =+(+T12+P12+R12-(I12*3))/I12 -> 5.9460249 | V12: A14-DB-N303
A13: 7 | B13: 10 | C13: A14-DB-N234 | D13: DOJC-SM-LC/PC-LC/PC | E13: 908040702, 20M, B3, 2.0mm | F13: =VLOOKUP(C13,'판매현황-통합'!$J$2:$M$1479,4,0) -> 10662 | G13: =VLOOKUP(C13,'판매현황-통합'!J:P,6,0) -> 2024/04 | H13: =VLOOKUP(C13,'판매현황-통합'!J:P,7,0) -> 987 | I13: =+F13/24 -> 444.25 | J13: =SUMIF(판매현황_2026!C:C,발주검토!C13,판매현황_2026!F:F)/4 -> 343.75 | K13: =+J13-I13 -> -100.5 | L13: =IF(K13<0,"감소","증가") -> 감소 | M13: =VLOOKUP(C13,'판매현황-통합'!$J$1:$Q$1420,8,0) -> Fiberwit Link Communication Co.,LTD | N13: =VLOOKUP(M13,리드타임!$B$3:$D$10,3,0) -> 60 | O13: =I13*3 -> 1332.75 | P13: =IFERROR(VLOOKUP(C13,재고현황!$A:$D,4,0),0) -> 791 | Q13: =+P13/I13 -> 1.780529 | R13: =SUMIF(입고예정_260527!C:C,발주검토!C13,입고예정_260527!F:F) -> 900 | S13: =+(R13+P13)/O13 -> 1.2688051 | T13: 2300 | U13: =+(+T13+P13+R13-(I13*3))/I13 -> 5.9836804 | V13: A14-DB-N313
A14: 53 | B14: 11 | C14: A14-SB-N265 | D14: SOJC-SM-SC/PC-SC/PC | E14: 908041392, 2M, B3, 3.0mm | F14: =VLOOKUP(C14,'판매현황-통합'!$J$2:$M$1479,4,0) -> 12845 | G14: =VLOOKUP(C14,'판매현황-통합'!J:P,6,0) -> 2026/02 | H14: =VLOOKUP(C14,'판매현황-통합'!J:P,7,0) -> 2570 | I14: =+F14/24 -> 535.20833 | J14: =SUMIF(판매현황_2026!C:C,발주검토!C14,판매현황_2026!F:F)/4 -> 960 | K14: =+J14-I14 -> 424.79167 | L14: =IF(K14<0,"감소","증가") -> 증가 | M14: =VLOOKUP(C14,'판매현황-통합'!$J$1:$Q$1420,8,0) -> Fiberwit Link Communication Co.,LTD | N14: =VLOOKUP(M14,리드타임!$B$3:$D$10,3,0) -> 60 | O14: =I14*3 -> 1605.625 | P14: =IFERROR(VLOOKUP(C14,재고현황!$A:$D,4,0),0) -> -200 | Q14: =+P14/I14 -> -0.37368626 | R14: =SUMIF(입고예정_260527!C:C,발주검토!C14,입고예정_260527!F:F) -> 1900 | S14: =+(R14+P14)/O14 -> 1.0587777 | T14: =I14*9-R14 -> 2916.875 | U14: =+(+T14+P14+R14-(I14*3))/I14 -> 5.6263137 | V14: A14-SB-N268
A15: 8 | B15: 12 | C15: 14-K-176 | D15: OJC-A1-SC/LC-SM-10-PC/PC-DP | E15: K9089162 | F15: =VLOOKUP(C15,'판매현황-통합'!$J$2:$M$1479,4,0) -> 9558 | G15: =VLOOKUP(C15,'판매현황-통합'!J:P,6,0) -> 2024/11 | H15: =VLOOKUP(C15,'판매현황-통합'!J:P,7,0) -> 4102 | I15: =+F15/24 -> 398.25 | J15: =SUMIF(판매현황_2026!C:C,발주검토!C15,판매현황_2026!F:F)/4 -> 162.5 | K15: =+J15-I15 -> -235.75 | L15: =IF(K15<0,"감소","증가") -> 감소 | M15: =VLOOKUP(C15,'판매현황-통합'!$J$1:$Q$1420,8,0) -> Fiberwit Link Communication Co.,LTD | N15: =VLOOKUP(M15,리드타임!$B$3:$D$10,3,0) -> 60 | O15: =I15*3 -> 1194.75 | P15: =IFERROR(VLOOKUP(C15,재고현황!$A:$D,4,0),0) -> 2310 | Q15: =+P15/I15 -> 5.8003766 | R15: =SUMIF(입고예정_260527!C:C,발주검토!C15,입고예정_260527!F:F) -> 0 | S15: =+(R15+P15)/O15 -> 1.9334589 | T15: 1300 | U15: =+(+T15+P15+R15-(I15*3))/I15 -> 6.0646579 | V15: A14-SB-N261
A16: 34 | B16: 13 | C16: A14-SB-N272 | D16: SOJC-SM-SC/PC-SC/PC | E16: 908041394, 5M, B3, 3.0mm | F16: =VLOOKUP(C16,'판매현황-통합'!$J$2:$M$1479,4,0) -> 10963 | G16: =VLOOKUP(C16,'판매현황-통합'!J:P,6,0) -> 2026/03 | H16: =VLOOKUP(C16,'판매현황-통합'!J:P,7,0) -> 1990 | I16: =+F16/24 -> 456.79167 | J16: =SUMIF(판매현황_2026!C:C,발주검토!C16,판매현황_2026!F:F)/4 -> 602.75 | K16: =+J16-I16 -> 145.95833 | L16: =IF(K16<0,"감소","증가") -> 증가 | M16: =VLOOKUP(C16,'판매현황-통합'!$J$1:$Q$1420,8,0) -> Fiberwit Link Communication Co.,LTD | N16: =VLOOKUP(M16,리드타임!$B$3:$D$10,3,0) -> 60 | O16: =I16*3 -> 1370.375 | P16: =IFERROR(VLOOKUP(C16,재고현황!$A:$D,4,0),0) -> 70 | Q16: =+P16/I16 -> 0.15324273 | R16: =SUMIF(입고예정_260527!C:C,발주검토!C16,입고예정_260527!F:F) -> 150 | S16: =+(R16+P16)/O16 -> 0.16054 | T16: =I16*9-R16 -> 3961.125 | U16: =+(+T16+P16+R16-(I16*3))/I16 -> 6.1532427 | V16: A14-SB-N265
A17: 13 | B17: 14 | C17: 14-K-214 | D17: OJC-A1-SC/LC-SM-2-PC/PC-DP | E17: K9089158 | F17: =VLOOKUP(C17,'판매현황-통합'!$J$2:$M$1479,4,0) -> 9086 | G17: =VLOOKUP(C17,'판매현황-통합'!J:P,6,0) -> 2024/11 | H17: =VLOOKUP(C17,'판매현황-통합'!J:P,7,0) -> 4241 | I17: =+F17/24 -> 378.58333 | J17: =SUMIF(판매현황_2026!C:C,발주검토!C17,판매현황_2026!F:F)/4 -> 193.75 | K17: =+J17-I17 -> -184.83333 | L17: =IF(K17<0,"감소","증가") -> 감소 | M17: =VLOOKUP(C17,'판매현황-통합'!$J$1:$Q$1420,8,0) -> Fiberwit Link Communication Co.,LTD | N17: =VLOOKUP(M17,리드타임!$B$3:$D$10,3,0) -> 60 | O17: =I17*3 -> 1135.75 | P17: =IFERROR(VLOOKUP(C17,재고현황!$A:$D,4,0),0) -> 2613 | Q17: =+P17/I17 -> 6.9020471 | R17: =SUMIF(입고예정_260527!C:C,발주검토!C17,입고예정_260527!F:F) -> 0 | S17: =+(R17+P17)/O17 -> 2.3006824 | T17: 1000 | U17: =+(+T17+P17+R17-(I17*3))/I17 -> 6.5434735 | V17: A14-SB-N272
A18: 44 | B18: 15 | C18: 14-K-199 | D18: OJC-A1-SC/LC-SM-1-PC/PC-SP | E18: K9089028 | F18: =VLOOKUP(C18,'판매현황-통합'!$J$2:$M$1479,4,0) -> 8912 | G18: =VLOOKUP(C18,'판매현황-통합'!J:P,6,0) -> 2024/01 | H18: =VLOOKUP(C18,'판매현황-통합'!J:P,7,0) -> 1460 | I18: =+F18/24 -> 371.33333 | J18: =SUMIF(판매현황_2026!C:C,발주검토!C18,판매현황_2026!F:F)/4 -> 232.5 | K18: =+J18-I18 -> -138.83333 | L18: =IF(K18<0,"감소","증가") -> 감소 | M18: =VLOOKUP(C18,'판매현황-통합'!$J$1:$Q$1420,8,0) -> Fiberwit Link Communication Co.,LTD | N18: =VLOOKUP(M18,리드타임!$B$3:$D$10,3,0) -> 60 | O18: =I18*3 -> 1114 | P18: =IFERROR(VLOOKUP(C18,재고현황!$A:$D,4,0),0) -> 326 | Q18: =+P18/I18 -> 0.87791741 | R18: =SUMIF(입고예정_260527!C:C,발주검토!C18,입고예정_260527!F:F) -> 2200 | S18: =+(R18+P18)/O18 -> 2.2675045 | T18: 800 | U18: =+(+T18+P18+R18-(I18*3))/I18 -> 5.956912 | V18: A14-D1-N035
A19: 33 | B19: 16 | C19: 14-K-291 | D19: OJC-A1-SC/SC-SM-10-PC/PC-SP | E19: K9089003 | F19: =VLOOKUP(C19,'판매현황-통합'!$J$2:$M$1479,4,0) -> 8557 | G19: =VLOOKUP(C19,'판매현황-통합'!J:P,6,0) -> 2025/11 | H19: =VLOOKUP(C19,'판매현황-통합'!J:P,7,0) -> 2257 | I19: =+F19/24 -> 356.54167 | J19: =SUMIF(판매현황_2026!C:C,발주검토!C19,판매현황_2026!F:F)/4 -> 176.5 | K19: =+J19-I19 -> -180.04167 | L19: =IF(K19<0,"감소","증가") -> 감소 | M19: =VLOOKUP(C19,'판매현황-통합'!$J$1:$Q$1420,8,0) -> Fiberwit Link Communication Co.,LTD | N19: =VLOOKUP(M19,리드타임!$B$3:$D$10,3,0) -> 60 | O19: =I19*3 -> 1069.625 | P19: =IFERROR(VLOOKUP(C19,재고현황!$A:$D,4,0),0) -> 1744 | Q19: =+P19/I19 -> 4.8914339 | R19: =SUMIF(입고예정_260527!C:C,발주검토!C19,입고예정_260527!F:F) -> 1500 | S19: =+(R19+P19)/O19 -> 3.0328386 | U19: =+(+T19+P19+R19-(I19*3))/I19 -> 6.0985158 | V19: A14-D1-N040
A20: 39 | B20: 17 | C20: A14-SB-N258 | D20: SOJC-SM-SC/PC-SC/PC | E20: 908041399, 10M, B3, 2.0mm | F20: =VLOOKUP(C20,'판매현황-통합'!$J$2:$M$1479,4,0) -> 9322 | G20: =VLOOKUP(C20,'판매현황-통합'!J:P,6,0) -> 2024/10 | H20: =VLOOKUP(C20,'판매현황-통합'!J:P,7,0) -> 685 | I20: =+F20/24 -> 388.41667 | J20: =SUMIF(판매현황_2026!C:C,발주검토!C20,판매현황_2026!F:F)/4 -> 416.25 | K20: =+J20-I20 -> 27.833333 | L20: =IF(K20<0,"감소","증가") -> 증가 | M20: =VLOOKUP(C20,'판매현황-통합'!$J$1:$Q$1420,8,0) -> Fiberwit Link Communication Co.,LTD | N20: =VLOOKUP(M20,리드타임!$B$3:$D$10,3,0) -> 60 | O20: =I20*3 -> 1165.25 | P20: =IFERROR(VLOOKUP(C20,재고현황!$A:$D,4,0),0) -> -200 | Q20: =+P20/I20 -> -0.51491096 | R20: =SUMIF(입고예정_260527!C:C,발주검토!C20,입고예정_260527!F:F) -> 1500 | S20: =+(R20+P20)/O20 -> 1.1156404 | T20: 2200 | U20: =+(+T20+P20+R20-(I20*3))/I20 -> 6.0109419 | V20: A14-SB-N263
A21: 24 | B21: 18 | C21: A14-DB-N244 | D21: DOJC-SM-LC/PC-LC/PC | E21: 908040997, 3M, B3, 3.0mm | F21: =VLOOKUP(C21,'판매현황-통합'!$J$2:$M$1479,4,0) -> 8614 | G21: =VLOOKUP(C21,'판매현황-통합'!J:P,6,0) -> 2025/02 | H21: =VLOOKUP(C21,'판매현황-통합'!J:P,7,0) -> 585 | I21: =+F21/24 -> 358.91667 | J21: =SUMIF(판매현황_2026!C:C,발주검토!C21,판매현황_2026!F:F)/4 -> 319.25 | K21: =+J21-I21 -> -39.666667 | L21: =IF(K21<0,"감소","증가") -> 감소 | M21: =VLOOKUP(C21,'판매현황-통합'!$J$1:$Q$1420,8,0) -> Fiberwit Link Communication Co.,LTD | N21: =VLOOKUP(M21,리드타임!$B$3:$D$10,3,0) -> 60 | O21: =I21*3 -> 1076.75 | P21: =IFERROR(VLOOKUP(C21,재고현황!$A:$D,4,0),0) -> 989 | Q21: =+P21/I21 -> 2.7555143 | R21: =SUMIF(입고예정_260527!C:C,발주검토!C21,입고예정_260527!F:F) -> 2200 | S21: =+(R21+P21)/O21 -> 2.9616903 | T21: 50 | U21: =+(+T21+P21+R21-(I21*3))/I21 -> 6.0243789 | V21: A14-SB-N251
A22: 22 | B22: 19 | C22: A14-DB-N474 | D22: DOJC-SM-SC/PC-SC/PC | E22: 908040221, 3M, B3, 3.0mm | F22: =VLOOKUP(C22,'판매현황-통합'!$J$2:$M$1479,4,0) -> 6979 | G22: =VLOOKUP(C22,'판매현황-통합'!J:P,6,0) -> 2024/08 | H22: =VLOOKUP(C22,'판매현황-통합'!J:P,7,0) -> 600 | I22: =+F22/24 -> 290.79167 | J22: =SUMIF(판매현황_2026!C:C,발주검토!C22,판매현황_2026!F:F)/4 -> 175.75 | K22: =+J22-I22 -> -115.04167 | L22: =IF(K22<0,"감소","증가") -> 감소 | M22: =VLOOKUP(C22,'판매현황-통합'!$J$1:$Q$1420,8,0) -> Fiberwit Link Communication Co.,LTD | N22: =VLOOKUP(M22,리드타임!$B$3:$D$10,3,0) -> 60 | O22: =I22*3 -> 872.375 | P22: =IFERROR(VLOOKUP(C22,재고현황!$A:$D,4,0),0) -> 1361 | Q22: =+P22/I22 -> 4.6803267 | R22: =SUMIF(입고예정_260527!C:C,발주검토!C22,입고예정_260527!F:F) -> 800 | S22: =+(R22+P22)/O22 -> 2.4771457 | T22: 500 | U22: =+(+T22+P22+R22-(I22*3))/I22 -> 6.1508812 | V22: A14-SB-N220
A23: 41 | B23: 20 | C23: 14-K-303 | D23: OJC-A1-SC/SC-SM-15-PC/PC-SP | E23: K9089008 | F23: =VLOOKUP(C23,'판매현황-통합'!$J$2:$M$1479,4,0) -> 6914 | G23: =VLOOKUP(C23,'판매현황-통합'!J:P,6,0) -> 2025/12 | H23: =VLOOKUP(C23,'판매현황-통합'!J:P,7,0) -> 812 | I23: =+F23/24 -> 288.08333 | J23: =SUMIF(판매현황_2026!C:C,발주검토!C23,판매현황_2026!F:F)/4 -> 174.5 | K23: =+J23-I23 -> -113.58333 | L23: =IF(K23<0,"감소","증가") -> 감소 | M23: =VLOOKUP(C23,'판매현황-통합'!$J$1:$Q$1420,8,0) -> Fiberwit Link Communication Co.,LTD | N23: =VLOOKUP(M23,리드타임!$B$3:$D$10,3,0) -> 60 | O23: =I23*3 -> 864.25 | P23: =IFERROR(VLOOKUP(C23,재고현황!$A:$D,4,0),0) -> 887 | Q23: =+P23/I23 -> 3.0789702 | R23: =SUMIF(입고예정_260527!C:C,발주검토!C23,입고예정_260527!F:F) -> 1600 | S23: =+(R23+P23)/O23 -> 2.8776396 | T23: 120 | U23: =+(+T23+P23+R23-(I23*3))/I23 -> 6.0494649 | V23: A14-SB-N221
A24: 1 | B24: 21 | C24: 14-P-025 | D24: PIGTAIL-SC/APC-SM-12C (SK성단용) | E24: 1.5M | F24: =VLOOKUP(C24,'판매현황-통합'!$J$2:$M$1479,4,0) -> 6405 | G24: =VLOOKUP(C24,'판매현황-통합'!J:P,6,0) -> 2024/03 | H24: =VLOOKUP(C24,'판매현황-통합'!J:P,7,0) -> 702 | I24: =+F24/24 -> 266.875 | J24: =SUMIF(판매현황_2026!C:C,발주검토!C24,판매현황_2026!F:F)/4 -> 139 | K24: =+J24-I24 -> -127.875 | L24: =IF(K24<0,"감소","증가") -> 감소 | M24: =VLOOKUP(C24,'판매현황-통합'!$J$1:$Q$1420,8,0) -> Huizhou Fibercan Industrial Co.,Ltd | N24: =VLOOKUP(M24,리드타임!$B$3:$D$10,3,0) -> 40 | O24: =I24*3 -> 800.625 | P24: =IFERROR(VLOOKUP(C24,재고현황!$A:$D,4,0),0) -> 1650 | Q24: =+P24/I24 -> 6.1826698 | R24: =SUMIF(입고예정_260527!C:C,발주검토!C24,입고예정_260527!F:F) -> 0 | S24: =+(R24+P24)/O24 -> 2.0608899 | T24: =I24*9-R24 -> 2401.875 | U24: =+(+T24+P24+R24-(I24*3))/I24 -> 12.18267 | V24: A14-SB-N210
A25: 32 | B25: 22 | C25: A14-DB-N274 | D25: DOJC-SM-LC/PC-SC/APC | E25: 908040907, 3M, B3, 3.0mm | F25: =VLOOKUP(C25,'판매현황-통합'!$J$2:$M$1479,4,0) -> 6918 | G25: =VLOOKUP(C25,'판매현황-통합'!J:P,6,0) -> 2024/12 | H25: =VLOOKUP(C25,'판매현황-통합'!J:P,7,0) -> 675 | I25: =+F25/24 -> 288.25 | J25: =SUMIF(판매현황_2026!C:C,발주검토!C25,판매현황_2026!F:F)/4 -> 298.75 | K25: =+J25-I25 -> 10.5 | L25: =IF(K25<0,"감소","증가") -> 증가 | M25: =VLOOKUP(C25,'판매현황-통합'!$J$1:$Q$1420,8,0) -> Fiberwit Link Communication Co.,LTD | N25: =VLOOKUP(M25,리드타임!$B$3:$D$10,3,0) -> 60 | O25: =I25*3 -> 864.75 | P25: =IFERROR(VLOOKUP(C25,재고현황!$A:$D,4,0),0) -> 692 | Q25: =+P25/I25 -> 2.4006938 | R25: =SUMIF(입고예정_260527!C:C,발주검토!C25,입고예정_260527!F:F) -> 1800 | S25: =+(R25+P25)/O25 -> 2.8817577 | T25: =ROUND(+I25*9-P25-R25,-1) -> 100 | U25: =+(+T25+P25+R25-(I25*3))/I25 -> 5.9921943 | V25: A14-SB-N203
A26: 36 | B26: 23 | C26: 14-K-322 | D26: OJC-A1-SC/SC-SM-20-PC/PC-SP | E26: K9089013 | F26: =VLOOKUP(C26,'판매현황-통합'!$J$2:$M$1479,4,0) -> 5960 | G26: =VLOOKUP(C26,'판매현황-통합'!J:P,6,0) -> 2025/12 | H26: =VLOOKUP(C26,'판매현황-통합'!J:P,7,0) -> 1110 | I26: =+F26/24 -> 248.33333 | J26: =SUMIF(판매현황_2026!C:C,발주검토!C26,판매현황_2026!F:F)/4 -> 71.75 | K26: =+J26-I26 -> -176.58333 | L26: =IF(K26<0,"감소","증가") -> 감소 | M26: =VLOOKUP(C26,'판매현황-통합'!$J$1:$Q$1420,8,0) -> Fiberwit Link Communication Co.,LTD | N26: =VLOOKUP(M26,리드타임!$B$3:$D$10,3,0) -> 60 | O26: =I26*3 -> 745 | P26: =IFERROR(VLOOKUP(C26,재고현황!$A:$D,4,0),0) -> 1334 | Q26: =+P26/I26 -> 5.3718121 | R26: =SUMIF(입고예정_260527!C:C,발주검토!C26,입고예정_260527!F:F) -> 1100 | S26: =+(R26+P26)/O26 -> 3.2671141 | U26: =+(+T26+P26+R26-(I26*3))/I26 -> 6.8013423 | V26: A14-S-SA/FA-B-N-006
A27: 38 | B27: 24 | C27: A14-DB-N455 | D27: DOJC-SM-SC/PC-SC/APC | E27: 908040251, 3M, B3, 3.0mm | F27: =VLOOKUP(C27,'판매현황-통합'!$J$2:$M$1479,4,0) -> 6725 | G27: =VLOOKUP(C27,'판매현황-통합'!J:P,6,0) -> 2024/05 | H27: =VLOOKUP(C27,'판매현황-통합'!J:P,7,0) -> 705 | I27: =+F27/24 -> 280.20833 | J27: =SUMIF(판매현황_2026!C:C,발주검토!C27,판매현황_2026!F:F)/4 -> 357.5 | K27: =+J27-I27 -> 77.291667 | L27: =IF(K27<0,"감소","증가") -> 증가 | M27: =VLOOKUP(C27,'판매현황-통합'!$J$1:$Q$1420,8,0) -> Fiberwit Link Communication Co.,LTD | N27: =VLOOKUP(M27,리드타임!$B$3:$D$10,3,0) -> 60 | O27: =I27*3 -> 840.625 | P27: =IFERROR(VLOOKUP(C27,재고현황!$A:$D,4,0),0) -> 0 | Q27: =+P27/I27 -> 0 | R27: =SUMIF(입고예정_260527!C:C,발주검토!C27,입고예정_260527!F:F) -> 1900 | S27: =+(R27+P27)/O27 -> 2.260223 | T27: =I27*9-R27 -> 621.875 | U27: =+(+T27+P27+R27-(I27*3))/I27 -> 6 | V27: A14-DB-N407
A28: 11 | B28: 25 | C28: A14-DB-N237 | D28: DOJC-SM-LC/PC-LC/PC | E28: 908040707, 25M, B3, 2.0mm | F28: =VLOOKUP(C28,'판매현황-통합'!$J$2:$M$1479,4,0) -> 6013 | G28: =VLOOKUP(C28,'판매현황-통합'!J:P,6,0) -> 2024/07 | H28: =VLOOKUP(C28,'판매현황-통합'!J:P,7,0) -> 488 | I28: =+F28/24 -> 250.54167 | J28: =SUMIF(판매현황_2026!C:C,발주검토!C28,판매현황_2026!F:F)/4 -> 182 | K28: =+J28-I28 -> -68.541667 | L28: =IF(K28<0,"감소","증가") -> 감소 | M28: =VLOOKUP(C28,'판매현황-통합'!$J$1:$Q$1420,8,0) -> Fiberwit Link Communication Co.,LTD | N28: =VLOOKUP(M28,리드타임!$B$3:$D$10,3,0) -> 60 | O28: =I28*3 -> 751.625 | P28: =IFERROR(VLOOKUP(C28,재고현황!$A:$D,4,0),0) -> 741 | Q28: =+P28/I28 -> 2.9575919 | R28: =SUMIF(입고예정_260527!C:C,발주검토!C28,입고예정_260527!F:F) -> 400 | S28: =+(R28+P28)/O28 -> 1.5180442 | T28: 1200 | U28: =+(+T28+P28+R28-(I28*3))/I28 -> 6.3437552 | V28: A14-DB-N181
A29: 15 | B29: 26 | C29: A14-DB-N289 | D29: DOJC-SM-LC/PC-SC/PC | E29: 908040873, 15M, B3, 2.0mm | F29: =VLOOKUP(C29,'판매현황-통합'!$J$2:$M$1479,4,0) -> 6057 | G29: =VLOOKUP(C29,'판매현황-통합'!J:P,6,0) -> 2024/08 | H29: =VLOOKUP(C29,'판매현황-통합'!J:P,7,0) -> 560 | I29: =+F29/24 -> 252.375 | J29: =SUMIF(판매현황_2026!C:C,발주검토!C29,판매현황_2026!F:F)/4 -> 230 | K29: =+J29-I29 -> -22.375 | L29: =IF(K29<0,"감소","증가") -> 감소 | M29: =VLOOKUP(C29,'판매현황-통합'!$J$1:$Q$1420,8,0) -> Fiberwit Link Communication Co.,LTD | N29: =VLOOKUP(M29,리드타임!$B$3:$D$10,3,0) -> 60 | O29: =I29*3 -> 757.125 | P29: =IFERROR(VLOOKUP(C29,재고현황!$A:$D,4,0),0) -> 520 | Q29: =+P29/I29 -> 2.060426 | R29: =SUMIF(입고예정_260527!C:C,발주검토!C29,입고예정_260527!F:F) -> 900 | S29: =+(R29+P29)/O29 -> 1.8755159 | T29: 900 | U29: =+(+T29+P29+R29-(I29*3))/I29 -> 6.1926696 | V29: A14-DB-N105
A30: 12 | B30: 27 | C30: 14-K-204 | D30: OJC-A1-SC/LC-SM-20-PC/PC-DP | E30: K9089164 | F30: =VLOOKUP(C30,'판매현황-통합'!$J$2:$M$1479,4,0) -> 5421 | G30: =VLOOKUP(C30,'판매현황-통합'!J:P,6,0) -> 2025/12 | H30: =VLOOKUP(C30,'판매현황-통합'!J:P,7,0) -> 1081 | I30: =+F30/24 -> 225.875 | J30: =SUMIF(판매현황_2026!C:C,발주검토!C30,판매현황_2026!F:F)/4 -> 106.25 | K30: =+J30-I30 -> -119.625 | L30: =IF(K30<0,"감소","증가") -> 감소 | M30: =VLOOKUP(C30,'판매현황-통합'!$J$1:$Q$1420,8,0) -> Fiberwit Link Communication Co.,LTD | N30: =VLOOKUP(M30,리드타임!$B$3:$D$10,3,0) -> 60 | O30: =I30*3 -> 677.625 | P30: =IFERROR(VLOOKUP(C30,재고현황!$A:$D,4,0),0) -> 2281 | Q30: =+P30/I30 -> 10.098506 | R30: =SUMIF(입고예정_260527!C:C,발주검토!C30,입고예정_260527!F:F) -> 0 | S30: =+(R30+P30)/O30 -> 3.3661686 | U30: =+(+T30+P30+R30-(I30*3))/I30 -> 7.0985058 | V30: A14-DB-N481
A31: 95 | B31: 28 | C31: 14-K-849 | D31: OJC-A1-SC/SC-SM-1-PC/PC-SP | E31: K9088994_포앤티 | F31: =VLOOKUP(C31,'판매현황-통합'!$J$2:$M$1479,4,0) -> 4628 | G31: =VLOOKUP(C31,'판매현황-통합'!J:P,6,0) -> 2024/07 | H31: =VLOOKUP(C31,'판매현황-통합'!J:P,7,0) -> 1500 | I31: =+F31/24 -> 192.83333 | J31: =SUMIF(판매현황_2026!C:C,발주검토!C31,판매현황_2026!F:F)/4 -> 7 | K31: =+J31-I31 -> -185.83333 | L31: =IF(K31<0,"감소","증가") -> 감소 | M31: =VLOOKUP(C31,'판매현황-통합'!$J$1:$Q$1420,8,0) -> Fiberwit Link Communication Co.,LTD | N31: =VLOOKUP(M31,리드타임!$B$3:$D$10,3,0) -> 60 | O31: =I31*3 -> 578.5 | P31: =IFERROR(VLOOKUP(C31,재고현황!$A:$D,4,0),0) -> 1159 | Q31: =+P31/I31 -> 6.0103717 | R31: =SUMIF(입고예정_260527!C:C,발주검토!C31,입고예정_260527!F:F) -> 0 | S31: =+(R31+P31)/O31 -> 2.0034572 | U31: =+(+T31+P31+R31-(I31*3))/I31 -> 3.0103717 | V31: A14-DB-N447
A32: 46 | B32: 29 | C32: A14-SB-N089 | D32: SOJC-SM-LC/PC-LC/PC | E32: 908040274, 15M, B3, 2.0mm | F32: =VLOOKUP(C32,'판매현황-통합'!$J$2:$M$1479,4,0) -> 4868 | G32: =VLOOKUP(C32,'판매현황-통합'!J:P,6,0) -> 2025/11 | H32: =VLOOKUP(C32,'판매현황-통합'!J:P,7,0) -> 615 | I32: =+F32/24 -> 202.83333 | J32: =SUMIF(판매현황_2026!C:C,발주검토!C32,판매현황_2026!F:F)/4 -> 69.25 | K32: =+J32-I32 -> -133.58333 | L32: =IF(K32<0,"감소","증가") -> 감소 | M32: =VLOOKUP(C32,'판매현황-통합'!$J$1:$Q$1420,8,0) -> Fiberwit Link Communication Co.,LTD | N32: =VLOOKUP(M32,리드타임!$B$3:$D$10,3,0) -> 60 | O32: =I32*3 -> 608.5 | P32: =IFERROR(VLOOKUP(C32,재고현황!$A:$D,4,0),0) -> 673 | Q32: =+P32/I32 -> 3.3179951 | R32: =SUMIF(입고예정_260527!C:C,발주검토!C32,입고예정_260527!F:F) -> 700 | S32: =+(R32+P32)/O32 -> 2.2563681 | T32: 500 | U32: =+(+T32+P32+R32-(I32*3))/I32 -> 6.2341824 | V32: A14-DB-N426
A33: 16 | B33: 30 | C33: 14-K-083 | D33: OJC-A1-LC/LC-SM-15-PC/PC-DP | E33: K9089177 | F33: =VLOOKUP(C33,'판매현황-통합'!$J$2:$M$1479,4,0) -> 4514 | G33: =VLOOKUP(C33,'판매현황-통합'!J:P,6,0) -> 2024/10 | H33: =VLOOKUP(C33,'판매현황-통합'!J:P,7,0) -> 657 | I33: =+F33/24 -> 188.08333 | J33: =SUMIF(판매현황_2026!C:C,발주검토!C33,판매현황_2026!F:F)/4 -> 56 | K33: =+J33-I33 -> -132.08333 | L33: =IF(K33<0,"감소","증가") -> 감소 | M33: =VLOOKUP(C33,'판매현황-통합'!$J$1:$Q$1420,8,0) -> Fiberwit Link Communication Co.,LTD | N33: =VLOOKUP(M33,리드타임!$B$3:$D$10,3,0) -> 60 | O33: =I33*3 -> 564.25 | P33: =IFERROR(VLOOKUP(C33,재고현황!$A:$D,4,0),0) -> 1631 | Q33: =+P33/I33 -> 8.6716881 | R33: =SUMIF(입고예정_260527!C:C,발주검토!C33,입고예정_260527!F:F) -> 500 | S33: =+(R33+P33)/O33 -> 3.7766947 | U33: =+(+T33+P33+R33-(I33*3))/I33 -> 8.3300842 | V33: A14-DB-N192
A34: 23 | B34: 31 | C34: A14-DB-N284 | D34: DOJC-SM-LC/PC-SC/PC | E34: 908040868, 10M, B3, 2.0mm | F34: =VLOOKUP(C34,'판매현황-통합'!$J$2:$M$1479,4,0) -> 5014 | G34: =VLOOKUP(C34,'판매현황-통합'!J:P,6,0) -> 2025/02 | H34: =VLOOKUP(C34,'판매현황-통합'!J:P,7,0) -> 453 | I34: =+F34/24 -> 208.91667 | J34: =SUMIF(판매현황_2026!C:C,발주검토!C34,판매현황_2026!F:F)/4 -> 188.75 | K34: =+J34-I34 -> -20.166667 | L34: =IF(K34<0,"감소","증가") -> 감소 | M34: =VLOOKUP(C34,'판매현황-통합'!$J$1:$Q$1420,8,0) -> Fiberwit Link Communication Co.,LTD | N34: =VLOOKUP(M34,리드타임!$B$3:$D$10,3,0) -> 60 | O34: =I34*3 -> 626.75 | P34: =IFERROR(VLOOKUP(C34,재고현황!$A:$D,4,0),0) -> 405 | Q34: =+P34/I34 -> 1.938572 | R34: =SUMIF(입고예정_260527!C:C,발주검토!C34,입고예정_260527!F:F) -> 850 | S34: =+(R34+P34)/O34 -> 2.0023933 | T34: =ROUND(+I34*9-P34-R34,-1) -> 630 | U34: =+(+T34+P34+R34-(I34*3))/I34 -> 6.0227363 | V34: A14-DB-N304
A35: 18 | B35: 32 | C35: 14-K-236 | D35: OJC-A1-SC/LC-SM-5-PC/PC-DP | E35: K9089161 | F35: =VLOOKUP(C35,'판매현황-통합'!$J$2:$M$1479,4,0) -> 4452 | G35: =VLOOKUP(C35,'판매현황-통합'!J:P,6,0) -> 2025/06 | H35: =VLOOKUP(C35,'판매현황-통합'!J:P,7,0) -> 983 | I35: =+F35/24 -> 185.5 | J35: =SUMIF(판매현황_2026!C:C,발주검토!C35,판매현황_2026!F:F)/4 -> 51 | K35: =+J35-I35 -> -134.5 | L35: =IF(K35<0,"감소","증가") -> 감소 | M35: =VLOOKUP(C35,'판매현황-통합'!$J$1:$Q$1420,8,0) -> Fiberwit Link Communication Co.,LTD | N35: =VLOOKUP(M35,리드타임!$B$3:$D$10,3,0) -> 60 | O35: =I35*3 -> 556.5 | P35: =IFERROR(VLOOKUP(C35,재고현황!$A:$D,4,0),0) -> 850 | Q35: =+P35/I35 -> 4.5822102 | R35: =SUMIF(입고예정_260527!C:C,발주검토!C35,입고예정_260527!F:F) -> 2100 | S35: =+(R35+P35)/O35 -> 5.3009883 | U35: =+(+T35+P35+R35-(I35*3))/I35 -> 12.902965 | V35: A14-D-LP/SP-B-N-004
A36: 30 | B36: 33 | C36: 14-K-290 | D36: OJC-A1-SC/SC-SM-10-PC/PC-DP | E36: K9089132 | F36: =VLOOKUP(C36,'판매현황-통합'!$J$2:$M$1479,4,0) -> 4451 | G36: =VLOOKUP(C36,'판매현황-통합'!J:P,6,0) -> 2025/12 | H36: =VLOOKUP(C36,'판매현황-통합'!J:P,7,0) -> 1289 | I36: =+F36/24 -> 185.45833 | J36: =SUMIF(판매현황_2026!C:C,발주검토!C36,판매현황_2026!F:F)/4 -> 73 | K36: =+J36-I36 -> -112.45833 | L36: =IF(K36<0,"감소","증가") -> 감소 | M36: =VLOOKUP(C36,'판매현황-통합'!$J$1:$Q$1420,8,0) -> Fiberwit Link Communication Co.,LTD | N36: =VLOOKUP(M36,리드타임!$B$3:$D$10,3,0) -> 60 | O36: =I36*3 -> 556.375 | P36: =IFERROR(VLOOKUP(C36,재고현황!$A:$D,4,0),0) -> 1930 | Q36: =+P36/I36 -> 10.40665 | R36: =SUMIF(입고예정_260527!C:C,발주검토!C36,입고예정_260527!F:F) -> 1300 | S36: =+(R36+P36)/O36 -> 5.805437 | U36: =+(+T36+P36+R36-(I36*3))/I36 -> 14.416311 | V36: A14-DB-N268
A37: 20 | B37: 34 | C37: 14-K-078 | D37: OJC-A1-LC/LC-SM-10-PC/PC-DP | E37: K9089176 | F37: =VLOOKUP(C37,'판매현황-통합'!$J$2:$M$1479,4,0) -> 4363 | G37: =VLOOKUP(C37,'판매현황-통합'!J:P,6,0) -> 2025/12 | H37: =VLOOKUP(C37,'판매현황-통합'!J:P,7,0) -> 900 | I37: =+F37/24 -> 181.79167 | J37: =SUMIF(판매현황_2026!C:C,발주검토!C37,판매현황_2026!F:F)/4 -> 54.75 | K37: =+J37-I37 -> -127.04167 | L37: =IF(K37<0,"감소","증가") -> 감소 | M37: =VLOOKUP(C37,'판매현황-통합'!$J$1:$Q$1420,8,0) -> Fiberwit Link Communication Co.,LTD | N37: =VLOOKUP(M37,리드타임!$B$3:$D$10,3,0) -> 60 | O37: =I37*3 -> 545.375 | P37: =IFERROR(VLOOKUP(C37,재고현황!$A:$D,4,0),0) -> 589 | Q37: =+P37/I37 -> 3.2399725 | R37: =SUMIF(입고예정_260527!C:C,발주검토!C37,입고예정_260527!F:F) -> 900 | S37: =+(R37+P37)/O37 -> 2.7302315 | T37: =ROUND(+I37*9-P37-R37,-1) -> 150 | U37: =+(+T37+P37+R37-(I37*3))/I37 -> 6.0158148 | V37: A14-DB-N246
A38: 58 | B38: 35 | C38: A14-SB-N134 | D38: SOJC-SM-LC/PC-SC/PC | E38: 15M, B3, 2.0mm | F38: =VLOOKUP(C38,'판매현황-통합'!$J$2:$M$1479,4,0) -> 4643 | G38: =VLOOKUP(C38,'판매현황-통합'!J:P,6,0) -> 2024/04 | H38: =VLOOKUP(C38,'판매현황-통합'!J:P,7,0) -> 796 | I38: =+F38/24 -> 193.45833 | J38: =SUMIF(판매현황_2026!C:C,발주검토!C38,판매현황_2026!F:F)/4 -> 216.25 | K38: =+J38-I38 -> 22.791667 | L38: =IF(K38<0,"감소","증가") -> 증가 | M38: =VLOOKUP(C38,'판매현황-통합'!$J$1:$Q$1420,8,0) -> Fiberwit Link Communication Co.,LTD | N38: =VLOOKUP(M38,리드타임!$B$3:$D$10,3,0) -> 60 | O38: =I38*3 -> 580.375 | P38: =IFERROR(VLOOKUP(C38,재고현황!$A:$D,4,0),0) -> 0 | Q38: =+P38/I38 -> 0 | R38: =SUMIF(입고예정_260527!C:C,발주검토!C38,입고예정_260527!F:F) -> 950 | S38: =+(R38+P38)/O38 -> 1.6368727 | T38: 800 | U38: =+(+T38+P38+R38-(I38*3))/I38 -> 6.0458755 | V38: A14-DB-N170
A39: 72 | B39: 36 | C39: A14-SB-N086 | D39: SOJC-SM-LC/PC-LC/PC | E39: 908040269, 10M, B3, 2.0mm | F39: =VLOOKUP(C39,'판매현황-통합'!$J$2:$M$1479,4,0) -> 4428 | G39: =VLOOKUP(C39,'판매현황-통합'!J:P,6,0) -> 2024/08 | H39: =VLOOKUP(C39,'판매현황-통합'!J:P,7,0) -> 600 | I39: =+F39/24 -> 184.5 | J39: =SUMIF(판매현황_2026!C:C,발주검토!C39,판매현황_2026!F:F)/4 -> 166.25 | K39: =+J39-I39 -> -18.25 | L39: =IF(K39<0,"감소","증가") -> 감소 | M39: =VLOOKUP(C39,'판매현황-통합'!$J$1:$Q$1420,8,0) -> Fiberwit Link Communication Co.,LTD | N39: =VLOOKUP(M39,리드타임!$B$3:$D$10,3,0) -> 60 | O39: =I39*3 -> 553.5 | P39: =IFERROR(VLOOKUP(C39,재고현황!$A:$D,4,0),0) -> 328 | Q39: =+P39/I39 -> 1.7777778 | R39: =SUMIF(입고예정_260527!C:C,발주검토!C39,입고예정_260527!F:F) -> 700 | S39: =+(R39+P39)/O39 -> 1.8572719 | T39: 650 | U39: =+(+T39+P39+R39-(I39*3))/I39 -> 6.0948509 | V39: A14-SB-N215
A40: 92 | B40: 37 | C40: A14-SB-N185 | D40: SOJC-SM-SC/APC-SC/APC | E40: 908041450, 3M, B3, 3.0mm | F40: =VLOOKUP(C40,'판매현황-통합'!$J$2:$M$1479,4,0) -> 4165 | G40: =VLOOKUP(C40,'판매현황-통합'!J:P,6,0) -> 2025/02 | H40: =VLOOKUP(C40,'판매현황-통합'!J:P,7,0) -> 640 | I40: =+F40/24 -> 173.54167 | J40: =SUMIF(판매현황_2026!C:C,발주검토!C40,판매현황_2026!F:F)/4 -> 137.5 | K40: =+J40-I40 -> -36.041667 | L40: =IF(K40<0,"감소","증가") -> 감소 | M40: =VLOOKUP(C40,'판매현황-통합'!$J$1:$Q$1420,8,0) -> Fiberwit Link Communication Co.,LTD | N40: =VLOOKUP(M40,리드타임!$B$3:$D$10,3,0) -> 60 | O40: =I40*3 -> 520.625 | P40: =IFERROR(VLOOKUP(C40,재고현황!$A:$D,4,0),0) -> 623 | Q40: =+P40/I40 -> 3.589916 | R40: =SUMIF(입고예정_260527!C:C,발주검토!C40,입고예정_260527!F:F) -> 1100 | S40: =+(R40+P40)/O40 -> 3.3094838 | U40: =+(+T40+P40+R40-(I40*3))/I40 -> 6.9284514 | V40: A14-SB-N218
A41: 10 | B41: 38 | C41: 14-K-188 | D41: OJC-A1-SC/LC-SM-15-PC/PC-DP | E41: K9089163 | F41: =VLOOKUP(C41,'판매현황-통합'!$J$2:$M$1479,4,0) -> 3976 | G41: =VLOOKUP(C41,'판매현황-통합'!J:P,6,0) -> 2024/12 | H41: =VLOOKUP(C41,'판매현황-통합'!J:P,7,0) -> 4004 | I41: =+F41/24 -> 165.66667 | J41: =SUMIF(판매현황_2026!C:C,발주검토!C41,판매현황_2026!F:F)/4 -> 95.25 | K41: =+J41-I41 -> -70.416667 | L41: =IF(K41<0,"감소","증가") -> 감소 | M41: =VLOOKUP(C41,'판매현황-통합'!$J$1:$Q$1420,8,0) -> Fiberwit Link Communication Co.,LTD | N41: =VLOOKUP(M41,리드타임!$B$3:$D$10,3,0) -> 60 | O41: =I41*3 -> 497 | P41: =IFERROR(VLOOKUP(C41,재고현황!$A:$D,4,0),0) -> 1448 | Q41: =+P41/I41 -> 8.7404427 | R41: =SUMIF(입고예정_260527!C:C,발주검토!C41,입고예정_260527!F:F) -> 0 | S41: =+(R41+P41)/O41 -> 2.9134809 | T41: 100 | U41: =+(+T41+P41+R41-(I41*3))/I41 -> 6.3440644 | V41: A14-D-LA/LA-B-N-007
...

Sheet RAW ▶
B3: 행 레이블 | C3: 2023 | D3: 2024 | E3: 2025 | F3: 2026 | G3: 총합계
B4: 14-A-002 | C4: 159000 | G4: 159000
B5: 14-A-002F | C5: 156000 | G5: 156000
B6: 14-A-002N | C6: 1349000 | G6: 1349000
B7: 14-A-003 | E7: 13000 | G7: 13000
B8: 14-A-004 | C8: 17500 | G8: 17500
B9: 14-A-005 | D9: 42000 | G9: 42000
B10: 14-A-005C | F10: 15000 | G10: 15000
B11: 14-A-007 | D11: 104000 | G11: 104000
B12: 14-A-018 | D12: 100 | G12: 100
B13: 14-A-019 | C13: 42000 | G13: 42000
B14: 14-C-377 | C14: 8000 | G14: 8000
B15: 14-C-378 | C15: 20000 | G15: 20000
B16: 14-C-379 | C16: 216000 | G16: 216000
B17: 14-C-380 | C17: 7000 | G17: 7000
B18: 14-C-381 | D18: 5000 | G18: 5000
B19: 14-C-542 | C19: 900 | G19: 900
B20: 14-C-543 | C20: 500 | G20: 500
B21: 14-C-567 | D21: 100 | G21: 100
B22: 14-K-031 | D22: 50 | G22: 50
B23: 14-K-035 | C23: 890 | G23: 890
B24: 14-K-039 | C24: 380 | G24: 380
B25: 14-K-044 | C25: 600 | G25: 600
B26: 14-K-052 | D26: 150 | G26: 150
B27: 14-K-058 | C27: 170 | G27: 170
B28: 14-K-065 | C28: 440 | G28: 440
B29: 14-K-078 | D29: 1608 | G29: 1608
B30: 14-K-079 | C30: 270 | G30: 270
B31: 14-K-083 | D31: 3850 | G31: 3850
B32: 14-K-085 | F32: 50 | G32: 50
B33: 14-K-087 | D33: 1560 | G33: 1560
B34: 14-K-091 | D34: 650 | G34: 650
B35: 14-K-093 | D35: 800 | G35: 800
B36: 14-K-094 | E36: 400 | G36: 400
B37: 14-K-096 | E37: 60 | G37: 60
B38: 14-K-097 | D38: 1425 | G38: 1425
B39: 14-K-098 | E39: 120 | G39: 120
B40: 14-K-099 | E40: 130 | G40: 130
B41: 14-K-103 | E41: 60 | G41: 60
B42: 14-K-107 | D42: 1350 | G42: 1350
...

Sheet 판매현황-통합
A1: 구분 | B1: 월별 | C1: 품목코드 | D1: 품목명 | E1: 규격 | F1: 수량 | G1: 최다판매연월 | H1: 최다 월판매수량 | J1: 합계 : 수량
A2: 1 | B2: 2024/01 | C2: 14-C-005 | D2: DROP-CABLE(LC/PC) | E2: 3M | F2: 50 | G2: =INDEX($B$2:$B$9999,MATCH(_xlfn.MAXIFS($F$2:$F$9999,$C$2:$C$9999,C2),$F$1:$F$9999,0)) -> 2024/01 | H2: =_xlfn.MAXIFS(F:F,C:C,C2,G:G,G2) -> 330 | J2: 품목코드 | K2: 품목명 | L2: 규격 | M2: 요약 | N2: 월 평균 판매량(24-25년) | O2: 최다판매연월 | P2: 최다 월판매수량 | Q2: 수입구매처 | R2: 리드타임 | S2: 안전재고
A3: 2 | B3: 2024/01 | C3: 14-C-006 | D3: DROP-CABLE(LC/PC) | E3: 5M | F3: 30 | G3: =INDEX($B$2:$B$9999,MATCH(_xlfn.MAXIFS($F$2:$F$9999,$C$2:$C$9999,C3),$F$1:$F$9999,0)) -> 2024/01 | H3: =_xlfn.MAXIFS(F:F,C:C,C3,G:G,G3) -> 150 | J3: 14-C-001 | K3: DROP-CABLE(LC/PC) | L3: 10M | M3: 340 | N3: =+M3/20 -> 17 | O3: =VLOOKUP(J3,$C$2:$G$9999,5,0) -> 2024/01 | P3: =VLOOKUP(J3,$C$2:$H$9999,6,0) -> 110 | Q3: =VLOOKUP(J3,'구매현황_2301-2603'!$E$2:$I$1312,5,0) -> #N/A | R3: =VLOOKUP(Q3,리드타임!$B$3:$D$10,3,0) -> #N/A | S3: =IFERROR(N3/20*R3,N3/20*90) -> 76.5
A4: 3 | B4: 2024/01 | C4: 14-C-026 | D4: DROP-CABLE(SC/APC) | E4: 5M | F4: 10 | G4: =INDEX($B$2:$B$9999,MATCH(_xlfn.MAXIFS($F$2:$F$9999,$C$2:$C$9999,C4),$F$1:$F$9999,0)) -> 2024/01 | H4: =_xlfn.MAXIFS(F:F,C:C,C4,G:G,G4) -> 200 | J4: 14-C-003 | K4: DROP-CABLE(LC/PC) | L4: 20M | M4: 230 | N4: =+M4/20 -> 11.5 | O4: =VLOOKUP(J4,$C$2:$G$9999,5,0) -> 2024/01 | P4: =VLOOKUP(J4,$C$2:$H$9999,6,0) -> 100 | Q4: =VLOOKUP(J4,'구매현황_2301-2603'!$E$2:$I$1312,5,0) -> #N/A | R4: =VLOOKUP(Q4,리드타임!$B$3:$D$10,3,0) -> #N/A | S4: =IFERROR(N4/20*R4,N4/20*90) -> 51.75
A5: 4 | B5: 2024/01 | C5: 14-C-048 | D5: DROP-CABLE(SC/PC) | E5: 1M | F5: 30 | G5: =INDEX($B$2:$B$9999,MATCH(_xlfn.MAXIFS($F$2:$F$9999,$C$2:$C$9999,C5),$F$1:$F$9999,0)) -> 2024/01 | H5: =_xlfn.MAXIFS(F:F,C:C,C5,G:G,G5) -> 200 | J5: 14-C-005 | K5: DROP-CABLE(LC/PC) | L5: 3M | M5: 1620 | N5: =+M5/20 -> 81 | O5: =VLOOKUP(J5,$C$2:$G$9999,5,0) -> 2024/01 | P5: =VLOOKUP(J5,$C$2:$H$9999,6,0) -> 330 | Q5: =VLOOKUP(J5,'구매현황_2301-2603'!$E$2:$I$1312,5,0) -> #N/A | R5: =VLOOKUP(Q5,리드타임!$B$3:$D$10,3,0) -> #N/A | S5: =IFERROR(N5/20*R5,N5/20*90) -> 364.5
A6: 5 | B6: 2024/01 | C6: 14-C-055 | D6: DROP-CABLE(SC/PC) | E6: 3M | F6: 10 | G6: =INDEX($B$2:$B$9999,MATCH(_xlfn.MAXIFS($F$2:$F$9999,$C$2:$C$9999,C6),$F$1:$F$9999,0)) -> 2024/01 | H6: =_xlfn.MAXIFS(F:F,C:C,C6,G:G,G6) -> 20 | J6: 14-C-006 | K6: DROP-CABLE(LC/PC) | L6: 5M | M6: 765 | N6: =+M6/20 -> 38.25 | O6: =VLOOKUP(J6,$C$2:$G$9999,5,0) -> 2024/01 | P6: =VLOOKUP(J6,$C$2:$H$9999,6,0) -> 150 | Q6: =VLOOKUP(J6,'구매현황_2301-2603'!$E$2:$I$1312,5,0) -> #N/A | R6: =VLOOKUP(Q6,리드타임!$B$3:$D$10,3,0) -> #N/A | S6: =IFERROR(N6/20*R6,N6/20*90) -> 172.125
A7: 6 | B7: 2024/01 | C7: 14-C-087 | D7: DROP-CABLE(SC/APC) | E7: 3M | F7: 40 | G7: =INDEX($B$2:$B$9999,MATCH(_xlfn.MAXIFS($F$2:$F$9999,$C$2:$C$9999,C7),$F$1:$F$9999,0)) -> 2024/01 | H7: =_xlfn.MAXIFS(F:F,C:C,C7,G:G,G7) -> 200 | J7: 14-C-009 | K7: DROP-CABLE(LC/PC-SC/APC) | L7: 10M | M7: 260 | N7: =+M7/20 -> 13 | O7: =VLOOKUP(J7,$C$2:$G$9999,5,0) -> 2024/01 | P7: =VLOOKUP(J7,$C$2:$H$9999,6,0) -> 110 | Q7: =VLOOKUP(J7,'구매현황_2301-2603'!$E$2:$I$1312,5,0) -> #N/A | R7: =VLOOKUP(Q7,리드타임!$B$3:$D$10,3,0) -> #N/A | S7: =IFERROR(N7/20*R7,N7/20*90) -> 58.5
A8: 7 | B8: 2024/01 | C8: 14-C-089 | D8: DROP-CABLE(SC/APC) | E8: 7M | F8: 10 | G8: =INDEX($B$2:$B$9999,MATCH(_xlfn.MAXIFS($F$2:$F$9999,$C$2:$C$9999,C8),$F$1:$F$9999,0)) -> 2024/01 | H8: =_xlfn.MAXIFS(F:F,C:C,C8,G:G,G8) -> 70 | J8: 14-C-010 | K8: DROP-CABLE(LC/PC-SC/APC) | L8: 20M | M8: 90 | N8: =+M8/20 -> 4.5 | O8: =VLOOKUP(J8,$C$2:$G$9999,5,0) -> 2024/01 | P8: =VLOOKUP(J8,$C$2:$H$9999,6,0) -> 50 | Q8: =VLOOKUP(J8,'구매현황_2301-2603'!$E$2:$I$1312,5,0) -> #N/A | R8: =VLOOKUP(Q8,리드타임!$B$3:$D$10,3,0) -> #N/A | S8: =IFERROR(N8/20*R8,N8/20*90) -> 20.25
A9: 8 | B9: 2024/01 | C9: 14-C-091 | D9: DROP-CABLE(SC/APC) | E9: 12M | F9: 10 | G9: =INDEX($B$2:$B$9999,MATCH(_xlfn.MAXIFS($F$2:$F$9999,$C$2:$C$9999,C9),$F$1:$F$9999,0)) -> 2024/01 | H9: =_xlfn.MAXIFS(F:F,C:C,C9,G:G,G9) -> 10 | J9: 14-C-013 | K9: DROP-CABLE(SC/APC) | L9: 10M | M9: 140 | N9: =+M9/20 -> 7 | O9: =VLOOKUP(J9,$C$2:$G$9999,5,0) -> 2024/01 | P9: =VLOOKUP(J9,$C$2:$H$9999,6,0) -> 50 | Q9: =VLOOKUP(J9,'구매현황_2301-2603'!$E$2:$I$1312,5,0) -> #N/A | R9: =VLOOKUP(Q9,리드타임!$B$3:$D$10,3,0) -> #N/A | S9: =IFERROR(N9/20*R9,N9/20*90) -> 31.5
A10: 9 | B10: 2024/01 | C10: 14-C-497 | D10: DROP-CABLE(LC/PC)-2C | E10: 4M | F10: 100 | G10: =INDEX($B$2:$B$9999,MATCH(_xlfn.MAXIFS($F$2:$F$9999,$C$2:$C$9999,C10),$F$1:$F$9999,0)) -> 2024/01 | H10: =_xlfn.MAXIFS(F:F,C:C,C10,G:G,G10) -> 100 | J10: 14-C-015 | K10: DROP-CABLE(SC/APC) | L10: 15M | M10: 64 | N10: =+M10/20 -> 3.2 | O10: =VLOOKUP(J10,$C$2:$G$9999,5,0) -> 2024/01 | P10: =VLOOKUP(J10,$C$2:$H$9999,6,0) -> 44 | Q10: =VLOOKUP(J10,'구매현황_2301-2603'!$E$2:$I$1312,5,0) -> #N/A | R10: =VLOOKUP(Q10,리드타임!$B$3:$D$10,3,0) -> #N/A | S10: =IFERROR(N10/20*R10,N10/20*90) -> 14.4
A11: 10 | B11: 2024/01 | C11: 14-C-626 | D11: DROP-CABLE(LC/PC-SC/PC) | E11: 70M | F11: -1 | G11: =INDEX($B$2:$B$9999,MATCH(_xlfn.MAXIFS($F$2:$F$9999,$C$2:$C$9999,C11),$F$1:$F$9999,0)) -> 2024/01 | H11: =_xlfn.MAXIFS(F:F,C:C,C11,G:G,G11) -> -1 | J11: 14-C-017 | K11: DROP-CABLE(SC/APC) | L11: 20M | M11: 30 | N11: =+M11/20 -> 1.5 | O11: =VLOOKUP(J11,$C$2:$G$9999,5,0) -> 2024/01 | P11: =VLOOKUP(J11,$C$2:$H$9999,6,0) -> 30 | Q11: =VLOOKUP(J11,'구매현황_2301-2603'!$E$2:$I$1312,5,0) -> #N/A | R11: =VLOOKUP(Q11,리드타임!$B$3:$D$10,3,0) -> #N/A | S11: =IFERROR(N11/20*R11,N11/20*90) -> 6.75
A12: 11 | B12: 2024/01 | C12: 14-C-628 | D12: DROP-CABLE(LC/PC-SC/PC)-2C | E12: 70M | F12: 1 | G12: =INDEX($B$2:$B$9999,MATCH(_xlfn.MAXIFS($F$2:$F$9999,$C$2:$C$9999,C12),$F$1:$F$9999,0)) -> 2024/01 | H12: =_xlfn.MAXIFS(F:F,C:C,C12,G:G,G12) -> 1 | J12: 14-C-018 | K12: DROP-CABLE(SC/APC) | L12: 25M | M12: 5 | N12: =+M12/20 -> 0.25 | O12: =VLOOKUP(J12,$C$2:$G$9999,5,0) -> 2024/01 | P12: =VLOOKUP(J12,$C$2:$H$9999,6,0) -> 5 | Q12: =VLOOKUP(J12,'구매현황_2301-2603'!$E$2:$I$1312,5,0) -> #N/A | R12: =VLOOKUP(Q12,리드타임!$B$3:$D$10,3,0) -> #N/A | S12: =IFERROR(N12/20*R12,N12/20*90) -> 1.125
A13: 12 | B13: 2024/01 | C13: 14-D-019 | D13: DOJC-MM(OM3)-LC/PC-LC/PC | E13: 30M | F13: 4 | G13: =INDEX($B$2:$B$9999,MATCH(_xlfn.MAXIFS($F$2:$F$9999,$C$2:$C$9999,C13),$F$1:$F$9999,0)) -> 2024/01 | H13: =_xlfn.MAXIFS(F:F,C:C,C13,G:G,G13) -> 13 | J13: 14-C-024 | K13: DROP-CABLE(SC/APC) | L13: 50M | M13: 11 | N13: =+M13/20 -> 0.55 | O13: =VLOOKUP(J13,$C$2:$G$9999,5,0) -> 2024/01 | P13: =VLOOKUP(J13,$C$2:$H$9999,6,0) -> 10 | Q13: =VLOOKUP(J13,'구매현황_2301-2603'!$E$2:$I$1312,5,0) -> #N/A | R13: =VLOOKUP(Q13,리드타임!$B$3:$D$10,3,0) -> #N/A | S13: =IFERROR(N13/20*R13,N13/20*90) -> 2.475
A14: 13 | B14: 2024/01 | C14: 14-D-021 | D14: DOJC-MM(OM3)-LC/PC-LC/PC | E14: 3M | F14: 23 | G14: =INDEX($B$2:$B$9999,MATCH(_xlfn.MAXIFS($F$2:$F$9999,$C$2:$C$9999,C14),$F$1:$F$9999,0)) -> 2024/01 | H14: =_xlfn.MAXIFS(F:F,C:C,C14,G:G,G14) -> 30 | J14: 14-C-026 | K14: DROP-CABLE(SC/APC) | L14: 5M | M14: 591 | N14: =+M14/20 -> 29.55 | O14: =VLOOKUP(J14,$C$2:$G$9999,5,0) -> 2024/01 | P14: =VLOOKUP(J14,$C$2:$H$9999,6,0) -> 200 | Q14: =VLOOKUP(J14,'구매현황_2301-2603'!$E$2:$I$1312,5,0) -> #N/A | R14: =VLOOKUP(Q14,리드타임!$B$3:$D$10,3,0) -> #N/A | S14: =IFERROR(N14/20*R14,N14/20*90) -> 132.975
A15: 14 | B15: 2024/01 | C15: 14-D-029 | D15: DOJC-MM(OM3)-LC/PC-SC/PC | E15: 10M | F15: 2 | G15: =INDEX($B$2:$B$9999,MATCH(_xlfn.MAXIFS($F$2:$F$9999,$C$2:$C$9999,C15),$F$1:$F$9999,0)) -> 2024/01 | H15: =_xlfn.MAXIFS(F:F,C:C,C15,G:G,G15) -> 2 | J15: 14-C-029 | K15: DROP-CABLE(SC/APC) | L15: 70M | M15: 7 | N15: =+M15/20 -> 0.35 | O15: =VLOOKUP(J15,$C$2:$G$9999,5,0) -> 2024/01 | P15: =VLOOKUP(J15,$C$2:$H$9999,6,0) -> 6 | Q15: =VLOOKUP(J15,'구매현황_2301-2603'!$E$2:$I$1312,5,0) -> #N/A | R15: =VLOOKUP(Q15,리드타임!$B$3:$D$10,3,0) -> #N/A | S15: =IFERROR(N15/20*R15,N15/20*90) -> 1.575
A16: 15 | B16: 2024/01 | C16: 14-D-083A | D16: DX-MM-OM1-LC/PC-SC/PC-5M | F16: 3 | G16: =INDEX($B$2:$B$9999,MATCH(_xlfn.MAXIFS($F$2:$F$9999,$C$2:$C$9999,C16),$F$1:$F$9999,0)) -> 2024/01 | H16: =_xlfn.MAXIFS(F:F,C:C,C16,G:G,G16) -> 30 | J16: 14-C-040 | K16: DROP-CABLE(SC/PC) | L16: 120M | M16: 10 | N16: =+M16/20 -> 0.5 | O16: =VLOOKUP(J16,$C$2:$G$9999,5,0) -> 2024/01 | P16: =VLOOKUP(J16,$C$2:$H$9999,6,0) -> 10 | Q16: =VLOOKUP(J16,'구매현황_2301-2603'!$E$2:$I$1312,5,0) -> #N/A | R16: =VLOOKUP(Q16,리드타임!$B$3:$D$10,3,0) -> #N/A | S16: =IFERROR(N16/20*R16,N16/20*90) -> 2.25
A17: 16 | B17: 2024/01 | C17: 14-D-228 | D17: DOJC-SM-LC/PC-LC/PC | E17: 15M | F17: 30 | G17: =INDEX($B$2:$B$9999,MATCH(_xlfn.MAXIFS($F$2:$F$9999,$C$2:$C$9999,C17),$F$1:$F$9999,0)) -> 2024/01 | H17: =_xlfn.MAXIFS(F:F,C:C,C17,G:G,G17) -> 110 | J17: 14-C-048 | K17: DROP-CABLE(SC/PC) | L17: 1M | M17: 620 | N17: =+M17/20 -> 31 | O17: =VLOOKUP(J17,$C$2:$G$9999,5,0) -> 2024/01 | P17: =VLOOKUP(J17,$C$2:$H$9999,6,0) -> 200 | Q17: =VLOOKUP(J17,'구매현황_2301-2603'!$E$2:$I$1312,5,0) -> #N/A | R17: =VLOOKUP(Q17,리드타임!$B$3:$D$10,3,0) -> #N/A | S17: =IFERROR(N17/20*R17,N17/20*90) -> 139.5
A18: 17 | B18: 2024/01 | C18: 14-D-234 | D18: DOJC-SM-LC/PC-LC/PC | E18: 20M | F18: 100 | G18: =INDEX($B$2:$B$9999,MATCH(_xlfn.MAXIFS($F$2:$F$9999,$C$2:$C$9999,C18),$F$1:$F$9999,0)) -> 2024/01 | H18: =_xlfn.MAXIFS(F:F,C:C,C18,G:G,G18) -> 100 | J18: 14-C-052 | K18: DROP-CABLE(SC/PC) | L18: 2M | M18: 80 | N18: =+M18/20 -> 4 | O18: =VLOOKUP(J18,$C$2:$G$9999,5,0) -> 2024/01 | P18: =VLOOKUP(J18,$C$2:$H$9999,6,0) -> 80 | Q18: =VLOOKUP(J18,'구매현황_2301-2603'!$E$2:$I$1312,5,0) -> #N/A | R18: =VLOOKUP(Q18,리드타임!$B$3:$D$10,3,0) -> #N/A | S18: =IFERROR(N18/20*R18,N18/20*90) -> 18
A19: 18 | B19: 2024/01 | C19: 14-D-237 | D19: DOJC-SM-LC/PC-LC/PC | E19: 25M | F19: 50 | G19: =INDEX($B$2:$B$9999,MATCH(_xlfn.MAXIFS($F$2:$F$9999,$C$2:$C$9999,C19),$F$1:$F$9999,0)) -> 2024/01 | H19: =_xlfn.MAXIFS(F:F,C:C,C19,G:G,G19) -> 200 | J19: 14-C-053 | K19: DROP-CABLE(SC/PC) | L19: 30M | M19: 2 | N19: =+M19/20 -> 0.1 | O19: =VLOOKUP(J19,$C$2:$G$9999,5,0) -> 2024/01 | P19: =VLOOKUP(J19,$C$2:$H$9999,6,0) -> 2 | Q19: =VLOOKUP(J19,'구매현황_2301-2603'!$E$2:$I$1312,5,0) -> #N/A | R19: =VLOOKUP(Q19,리드타임!$B$3:$D$10,3,0) -> #N/A | S19: =IFERROR(N19/20*R19,N19/20*90) -> 0.45
A20: 19 | B20: 2024/01 | C20: 14-D-241 | D20: DOJC-SM-LC/PC-LC/PC | E20: 30M | F20: 70 | G20: =INDEX($B$2:$B$9999,MATCH(_xlfn.MAXIFS($F$2:$F$9999,$C$2:$C$9999,C20),$F$1:$F$9999,0)) -> 2024/01 | H20: =_xlfn.MAXIFS(F:F,C:C,C20,G:G,G20) -> 70 | J20: 14-C-055 | K20: DROP-CABLE(SC/PC) | L20: 3M | M20: 60 | N20: =+M20/20 -> 3 | O20: =VLOOKUP(J20,$C$2:$G$9999,5,0) -> 2024/01 | P20: =VLOOKUP(J20,$C$2:$H$9999,6,0) -> 20 | Q20: =VLOOKUP(J20,'구매현황_2301-2603'!$E$2:$I$1312,5,0) -> #N/A | R20: =VLOOKUP(Q20,리드타임!$B$3:$D$10,3,0) -> #N/A | S20: =IFERROR(N20/20*R20,N20/20*90) -> 13.5
A21: 20 | B21: 2024/01 | C21: 14-D-243 | D21: DOJC-SM-LC/PC-LC/PC | E21: 35M | F21: 50 | G21: =INDEX($B$2:$B$9999,MATCH(_xlfn.MAXIFS($F$2:$F$9999,$C$2:$C$9999,C21),$F$1:$F$9999,0)) -> 2024/01 | H21: =_xlfn.MAXIFS(F:F,C:C,C21,G:G,G21) -> 50 | J21: 14-C-059 | K21: DROP-CABLE(SC/PC) | L21: 50M | M21: 21 | N21: =+M21/20 -> 1.05 | O21: =VLOOKUP(J21,$C$2:$G$9999,5,0) -> 2024/01 | P21: =VLOOKUP(J21,$C$2:$H$9999,6,0) -> 20 | Q21: =VLOOKUP(J21,'구매현황_2301-2603'!$E$2:$I$1312,5,0) -> #N/A | R21: =VLOOKUP(Q21,리드타임!$B$3:$D$10,3,0) -> #N/A | S21: =IFERROR(N21/20*R21,N21/20*90) -> 4.725
A22: 21 | B22: 2024/01 | C22: 14-D-244 | D22: DOJC-SM-LC/PC-LC/PC | E22: 3M | F22: 70 | G22: =INDEX($B$2:$B$9999,MATCH(_xlfn.MAXIFS($F$2:$F$9999,$C$2:$C$9999,C22),$F$1:$F$9999,0)) -> 2024/01 | H22: =_xlfn.MAXIFS(F:F,C:C,C22,G:G,G22) -> 100 | J22: 14-C-061 | K22: DROP-CABLE(SC/PC) | L22: 5M | M22: 5 | N22: =+M22/20 -> 0.25 | O22: =VLOOKUP(J22,$C$2:$G$9999,5,0) -> 2024/01 | P22: =VLOOKUP(J22,$C$2:$H$9999,6,0) -> 5 | Q22: =VLOOKUP(J22,'구매현황_2301-2603'!$E$2:$I$1312,5,0) -> #N/A | R22: =VLOOKUP(Q22,리드타임!$B$3:$D$10,3,0) -> #N/A | S22: =IFERROR(N22/20*R22,N22/20*90) -> 1.125
A23: 22 | B23: 2024/01 | C23: 14-D-256 | D23: DOJC-SM-LC/PC-LC/PC | E23: 6M | F23: 100 | G23: =INDEX($B$2:$B$9999,MATCH(_xlfn.MAXIFS($F$2:$F$9999,$C$2:$C$9999,C23),$F$1:$F$9999,0)) -> 2024/01 | H23: =_xlfn.MAXIFS(F:F,C:C,C23,G:G,G23) -> 1000 | J23: 14-C-062 | K23: DROP-CABLE(SC/PC) | L23: 60M | M23: 20 | N23: =+M23/20 -> 1 | O23: =VLOOKUP(J23,$C$2:$G$9999,5,0) -> 2024/01 | P23: =VLOOKUP(J23,$C$2:$H$9999,6,0) -> 20 | Q23: =VLOOKUP(J23,'구매현황_2301-2603'!$E$2:$I$1312,5,0) -> #N/A | R23: =VLOOKUP(Q23,리드타임!$B$3:$D$10,3,0) -> #N/A | S23: =IFERROR(N23/20*R23,N23/20*90) -> 4.5
A24: 23 | B24: 2024/01 | C24: 14-D-436 | D24: DOJC-SM-SC/PC-FC/PC | E24: 3M | F24: 2 | G24: =INDEX($B$2:$B$9999,MATCH(_xlfn.MAXIFS($F$2:$F$9999,$C$2:$C$9999,C24),$F$1:$F$9999,0)) -> 2024/01 | H24: =_xlfn.MAXIFS(F:F,C:C,C24,G:G,G24) -> 4 | J24: 14-C-065 | K24: DROP-CABLE(SC/PC) | L24: 70M | M24: 30 | N24: =+M24/20 -> 1.5 | O24: =VLOOKUP(J24,$C$2:$G$9999,5,0) -> 2024/01 | P24: =VLOOKUP(J24,$C$2:$H$9999,6,0) -> 20 | Q24: =VLOOKUP(J24,'구매현황_2301-2603'!$E$2:$I$1312,5,0) -> #N/A | R24: =VLOOKUP(Q24,리드타임!$B$3:$D$10,3,0) -> #N/A | S24: =IFERROR(N24/20*R24,N24/20*90) -> 6.75
A25: 24 | B25: 2024/01 | C25: 14-D-601 | D25: DOJC-SM-LC/PC-SC/PC | E25: 0.3M | F25: 5 | G25: =INDEX($B$2:$B$9999,MATCH(_xlfn.MAXIFS($F$2:$F$9999,$C$2:$C$9999,C25),$F$1:$F$9999,0)) -> 2024/01 | H25: =_xlfn.MAXIFS(F:F,C:C,C25,G:G,G25) -> 5 | J25: 14-C-067 | K25: DROP-CABLE(SC/PC) | L25: 7M | M25: 740 | N25: =+M25/20 -> 37 | O25: =VLOOKUP(J25,$C$2:$G$9999,5,0) -> 2024/01 | P25: =VLOOKUP(J25,$C$2:$H$9999,6,0) -> 200 | Q25: =VLOOKUP(J25,'구매현황_2301-2603'!$E$2:$I$1312,5,0) -> #N/A | R25: =VLOOKUP(Q25,리드타임!$B$3:$D$10,3,0) -> #N/A | S25: =IFERROR(N25/20*R25,N25/20*90) -> 166.5
A26: 25 | B26: 2024/01 | C26: 14-D-733 | D26: DOJC-SM-LC/PC-LC/PC | E26: 20M_청색케이블 | F26: 30 | G26: =INDEX($B$2:$B$9999,MATCH(_xlfn.MAXIFS($F$2:$F$9999,$C$2:$C$9999,C26),$F$1:$F$9999,0)) -> 2024/01 | H26: =_xlfn.MAXIFS(F:F,C:C,C26,G:G,G26) -> 40 | J26: 14-C-068 | K26: DROP-CABLE(SC/PC) | L26: 80M | M26: 20 | N26: =+M26/20 -> 1 | O26: =VLOOKUP(J26,$C$2:$G$9999,5,0) -> 2024/01 | P26: =VLOOKUP(J26,$C$2:$H$9999,6,0) -> 10 | Q26: =VLOOKUP(J26,'구매현황_2301-2603'!$E$2:$I$1312,5,0) -> #N/A | R26: =VLOOKUP(Q26,리드타임!$B$3:$D$10,3,0) -> #N/A | S26: =IFERROR(N26/20*R26,N26/20*90) -> 4.5
A27: 26 | B27: 2024/01 | C27: 14-D-734 | D27: DOJC-SM-LC/PC-LC/PC | E27: 25M_청색케이블 | F27: 30 | G27: =INDEX($B$2:$B$9999,MATCH(_xlfn.MAXIFS($F$2:$F$9999,$C$2:$C$9999,C27),$F$1:$F$9999,0)) -> 2024/01 | H27: =_xlfn.MAXIFS(F:F,C:C,C27,G:G,G27) -> 30 | J27: 14-C-072 | K27: DROP-CABLE(SC/PC) | L27: 90M | M27: 20 | N27: =+M27/20 -> 1 | O27: =VLOOKUP(J27,$C$2:$G$9999,5,0) -> 2024/01 | P27: =VLOOKUP(J27,$C$2:$H$9999,6,0) -> 10 | Q27: =VLOOKUP(J27,'구매현황_2301-2603'!$E$2:$I$1312,5,0) -> #N/A | R27: =VLOOKUP(Q27,리드타임!$B$3:$D$10,3,0) -> #N/A | S27: =IFERROR(N27/20*R27,N27/20*90) -> 4.5
A28: 27 | B28: 2024/01 | C28: 14-D-735 | D28: DOJC-SM-LC/PC-LC/PC | E28: 35M_청색케이블 | F28: 10 | G28: =INDEX($B$2:$B$9999,MATCH(_xlfn.MAXIFS($F$2:$F$9999,$C$2:$C$9999,C28),$F$1:$F$9999,0)) -> 2024/01 | H28: =_xlfn.MAXIFS(F:F,C:C,C28,G:G,G28) -> 10 | J28: 14-C-076 | K28: DROP-CABLE(SC/PC-SC/APC) | L28: 25M | M28: 30 | N28: =+M28/20 -> 1.5 | O28: =VLOOKUP(J28,$C$2:$G$9999,5,0) -> 2024/01 | P28: =VLOOKUP(J28,$C$2:$H$9999,6,0) -> 30 | Q28: =VLOOKUP(J28,'구매현황_2301-2603'!$E$2:$I$1312,5,0) -> #N/A | R28: =VLOOKUP(Q28,리드타임!$B$3:$D$10,3,0) -> #N/A | S28: =IFERROR(N28/20*R28,N28/20*90) -> 6.75
... A75: 74 | B75: 2024/01 | C75: 14-K-361 | D75: OJC-A1-SC/SC-SM-3-PC/PC-DP | E75: K9089125 | F75: 154 | G75: =INDEX($B$2:$B$9999,MATCH(_xlfn.MAXIFS($F$2:$F$9999,$C$2:$C$9999,C75),$F$1:$F$9999,0)) -> 2024/10 | H75: =_xlfn.MAXIFS(F:F,C:C,C75,G:G,G75) -> 510 | J75: 14-C-506 | K75: Optical Cable Parts,SC/PC-LC/PC-Single mode-5m-2Core | L75: 657A2 , LSZH , LC DUPLEX KIT(CLIP),95MM/ 500MM | M75: 18 | N75: =+M75/20 -> 0.9 | O75: =VLOOKUP(J75,$C$2:$G$9999,5,0) -> 2024/01 | P75: =VLOOKUP(J75,$C$2:$H$9999,6,0) -> 18 | Q75: =VLOOKUP(J75,'구매현황_2301-2603'!$E$2:$I$1312,5,0) -> #N/A | R75: =VLOOKUP(Q75,리드타임!$B$3:$D$10,3,0) -> #N/A | S75: =IFERROR(N75/20*R75,N75/20*90) -> 4.05
A76: 75 | B76: 2024/01 | C76: 14-K-362 | D76: OJC-A1-SC/SC-SM-3-PC/PC-SP | E76: K9088996 | F76: 3107 | G76: =INDEX($B$2:$B$9999,MATCH(_xlfn.MAXIFS($F$2:$F$9999,$C$2:$C$9999,C76),$F$1:$F$9999,0)) -> 2025/12 | H76: =_xlfn.MAXIFS(F:F,C:C,C76,G:G,G76) -> 32271 | J76: 14-C-520 | K76: Optical Cable Parts,LC/PC-LC/PC-Single mode-70m-1Core | L76: 657A2 , LSZH | N76: =+M76/20 -> 0 | O76: =VLOOKUP(J76,$C$2:$G$9999,5,0) -> #N/A | P76: =VLOOKUP(J76,$C$2:$H$9999,6,0) -> 0 | Q76: =VLOOKUP(J76,'구매현황_2301-2603'!$E$2:$I$1312,5,0) -> #N/A | R76: =VLOOKUP(Q76,리드타임!$B$3:$D$10,3,0) -> #N/A | S76: =IFERROR(N76/20*R76,N76/20*90) -> 0
A77: 76 | B77: 2024/01 | C77: 14-K-375 | D77: OJC-A1-SC/SC-SM-5-APC/APC-SP | F77: 55 | G77: =INDEX($B$2:$B$9999,MATCH(_xlfn.MAXIFS($F$2:$F$9999,$C$2:$C$9999,C77),$F$1:$F$9999,0)) -> 2024/01 | H77: =_xlfn.MAXIFS(F:F,C:C,C77,G:G,G77) -> 100 | J77: 14-C-534 | K77: DROP-CABLE(LC/PC-SC/APC) | L77: 25M | M77: 5 | N77: =+M77/20 -> 0.25 | O77: =VLOOKUP(J77,$C$2:$G$9999,5,0) -> 2024/01 | P77: =VLOOKUP(J77,$C$2:$H$9999,6,0) -> 5 | Q77: =VLOOKUP(J77,'구매현황_2301-2603'!$E$2:$I$1312,5,0) -> #N/A | R77: =VLOOKUP(Q77,리드타임!$B$3:$D$10,3,0) -> #N/A | S77: =IFERROR(N77/20*R77,N77/20*90) -> 1.125
A78: 77 | B78: 2024/01 | C78: 14-K-378 | D78: OJC-A1-SC/SC-SM-5-PC/PC-DP | E78: K9089127 | F78: 90 | G78: =INDEX($B$2:$B$9999,MATCH(_xlfn.MAXIFS($F$2:$F$9999,$C$2:$C$9999,C78),$F$1:$F$9999,0)) -> 2025/12 | H78: =_xlfn.MAXIFS(F:F,C:C,C78,G:G,G78) -> 868 | J78: 14-C-535 | K78: Optical Cable Parts,LC/PC-LC/PC-Single mode-15m-2Core | L78: 657A2 , LSZH , LC DUPLEX KIT(CLIP), 300MM/ 300MM | M78: 250 | N78: =+M78/20 -> 12.5 | O78: =VLOOKUP(J78,$C$2:$G$9999,5,0) -> 2024/01 | P78: =VLOOKUP(J78,$C$2:$H$9999,6,0) -> 50 | Q78: =VLOOKUP(J78,'구매현황_2301-2603'!$E$2:$I$1312,5,0) -> #N/A | R78: =VLOOKUP(Q78,리드타임!$B$3:$D$10,3,0) -> #N/A | S78: =IFERROR(N78/20*R78,N78/20*90) -> 56.25
A79: 78 | B79: 2024/01 | C79: 14-K-379 | D79: OJC-A1-SC/SC-SM-5-PC/PC-SP | E79: K9088998 | F79: 8 | G79: =INDEX($B$2:$B$9999,MATCH(_xlfn.MAXIFS($F$2:$F$9999,$C$2:$C$9999,C79),$F$1:$F$9999,0)) -> 2024/10 | H79: =_xlfn.MAXIFS(F:F,C:C,C79,G:G,G79) -> 527 | J79: 14-C-542 | K79: DROP-CABLE(LC/UPC)-2C | L79: 0.72M, CLIP Type, 청색 Housing, 분기부 스프링, 크로스 타입(TX-RX, RX-TX) | M79: 370 | N79: =+M79/20 -> 18.5 | O79: =VLOOKUP(J79,$C$2:$G$9999,5,0) -> 2024/01 | P79: =VLOOKUP(J79,$C$2:$H$9999,6,0) -> 100 | Q79: =VLOOKUP(J79,'구매현황_2301-2603'!$E$2:$I$1312,5,0) -> Shenzhen Fibercan Optical Co., Ltd | R79: =VLOOKUP(Q79,리드타임!$B$3:$D$10,3,0) -> 40 | S79: =IFERROR(N79/20*R79,N79/20*90) -> 37
A80: 79 | B80: 2024/01 | C80: 14-K-385 | D80: OJC-A1-SC/SC-SM-6-PC/PC-SP | E80: K9088999 | F80: 32 | G80: =INDEX($B$2:$B$9999,MATCH(_xlfn.MAXIFS($F$2:$F$9999,$C$2:$C$9999,C80),$F$1:$F$9999,0)) -> 2024/01 | H80: =_xlfn.MAXIFS(F:F,C:C,C80,G:G,G80) -> 32 | J80: 14-C-543 | K80: DROP-CABLE(LC/UPC)-2C | L80: 2M, CLIP Type, 청색 Housing, 분기부 스프링, 크로스 타입(TX-RX, RX-TX) | M80: 168 | N80: =+M80/20 -> 8.4 | O80: =VLOOKUP(J80,$C$2:$G$9999,5,0) -> 2024/07 | P80: =VLOOKUP(J80,$C$2:$H$9999,6,0) -> 134 | Q80: =VLOOKUP(J80,'구매현황_2301-2603'!$E$2:$I$1312,5,0) -> Shenzhen Fibercan Optical Co., Ltd | R80: =VLOOKUP(Q80,리드타임!$B$3:$D$10,3,0) -> 40 | S80: =IFERROR(N80/20*R80,N80/20*90) -> 16.8
A81: 80 | B81: 2024/01 | C81: 14-K-640 | D81: OJC-A1-LC/LC-MM-7-PC/PC-DP | F81: 4 | G81: =INDEX($B$2:$B$9999,MATCH(_xlfn.MAXIFS($F$2:$F$9999,$C$2:$C$9999,C81),$F$1:$F$9999,0)) -> 2024/01 | H81: =_xlfn.MAXIFS(F:F,C:C,C81,G:G,G81) -> 4 | J81: 14-C-552 | K81: Optical Cable Parts,LC/PC-LC/PC-Single mode-10m-2Core | L81: 657A2 , LSZH , LC DUPLEX KIT(CLIP), 0MM/ 300MM | M81: 200 | N81: =+M81/20 -> 10 | O81: =VLOOKUP(J81,$C$2:$G$9999,5,0) -> 2024/01 | P81: =VLOOKUP(J81,$C$2:$H$9999,6,0) -> 50 | Q81: =VLOOKUP(J81,'구매현황_2301-2603'!$E$2:$I$1312,5,0) -> #N/A | R81: =VLOOKUP(Q81,리드타임!$B$3:$D$10,3,0) -> #N/A | S81: =IFERROR(N81/20*R81,N81/20*90) -> 45
A82: 81 | B82: 2024/01 | C82: 14-K-732 | D82: OJC-C2-SC/SC-SM-20-PC/PC-16C | E82: K9094339 | F82: 5 | G82: =INDEX($B$2:$B$9999,MATCH(_xlfn.MAXIFS($F$2:$F$9999,$C$2:$C$9999,C82),$F$1:$F$9999,0)) -> 2024/01 | H82: =_xlfn.MAXIFS(F:F,C:C,C82,G:G,G82) -> 5 | J82: 14-C-553 | K82: Optical Cable Parts,LC/PC-LC/PC-Single mode-15m-2Core | L82: 657A2 , LSZH , LC DUPLEX KIT(CLIP), 0MM/ 300MM | M82: 250 | N82: =+M82/20 -> 12.5 | O82: =VLOOKUP(J82,$C$2:$G$9999,5,0) -> 2024/01 | P82: =VLOOKUP(J82,$C$2:$H$9999,6,0) -> 100 | Q82: =VLOOKUP(J82,'구매현황_2301-2603'!$E$2:$I$1312,5,0) -> #N/A | R82: =VLOOKUP(Q82,리드타임!$B$3:$D$10,3,0) -> #N/A | S82: =IFERROR(N82/20*R82,N82/20*90) -> 56.25
A83: 82 | B83: 2024/01 | C83: 14-K-829 | D83: OJC-A1-SC/SC-SM-55-PC/PC-DP | F83: 2 | G83: =INDEX($B$2:$B$9999,MATCH(_xlfn.MAXIFS($F$2:$F$9999,$C$2:$C$9999,C83),$F$1:$F$9999,0)) -> 2024/01 | H83: =_xlfn.MAXIFS(F:F,C:C,C83,G:G,G83) -> 2 | J83: 14-C-554 | K83: Optical Cable Parts,LC/PC-LC/PC-Single mode-20m-2Core | L83: 657A2 , LSZH , LC DUPLEX KIT(CLIP), 0MM/ 300MM | M83: 230 | N83: =+M83/20 -> 11.5 | O83: =VLOOKUP(J83,$C$2:$G$9999,5,0) -> 2024/01 | P83: =VLOOKUP(J83,$C$2:$H$9999,6,0) -> 100 | Q83: =VLOOKUP(J83,'구매현황_2301-2603'!$E$2:$I$1312,5,0) -> #N/A | R83: =VLOOKUP(Q83,리드타임!$B$3:$D$10,3,0) -> #N/A | S83: =IFERROR(N83/20*R83,N83/20*90) -> 51.75
A84: 83 | B84: 2024/01 | C84: 14-K-847 | D84: OJC-A1-SC/SC-SM-2-PC/PC-SP | E84: K9088995_고려오트론 | F84: 1480 | G84: =INDEX($B$2:$B$9999,MATCH(_xlfn.MAXIFS($F$2:$F$9999,$C$2:$C$9999,C84),$F$1:$F$9999,0)) -> 2024/01 | H84: =_xlfn.MAXIFS(F:F,C:C,C84,G:G,G84) -> 1480 | J84: 14-C-555 | K84: Optical Cable Parts,LC/PC-LC/PC-Single mode-25m-2Core | L84: 657A2 , LSZH , LC DUPLEX KIT(CLIP), 0MM/ 300MM | M84: 30 | N84: =+M84/20 -> 1.5 | O84: =VLOOKUP(J84,$C$2:$G$9999,5,0) -> 2024/01 | P84: =VLOOKUP(J84,$C$2:$H$9999,6,0) -> 30 | Q84: =VLOOKUP(J84,'구매현황_2301-2603'!$E$2:$I$1312,5,0) -> #N/A | R84: =VLOOKUP(Q84,리드타임!$B$3:$D$10,3,0) -> #N/A | S84: =IFERROR(N84/20*R84,N84/20*90) -> 6.75
A85: 84 | B85: 2024/01 | C85: 14-K-850 | D85: OJC-A1-SC/SC-SM-2-PC/PC-SP | E85: K9088995_포앤티 | F85: 1000 | G85: =INDEX($B$2:$B$9999,MATCH(_xlfn.MAXIFS($F$2:$F$9999,$C$2:$C$9999,C85),$F$1:$F$9999,0)) -> 2024/01 | H85: =_xlfn.MAXIFS(F:F,C:C,C85,G:G,G85) -> 1000 | J85: 14-C-556 | K85: Optical Cable Parts,LC/PC-LC/PC-Single mode-30m-2Core | L85: 657A2 , LSZH , LC DUPLEX KIT(CLIP), 0MM/ 300MM | M85: 60 | N85: =+M85/20 -> 3 | O85: =VLOOKUP(J85,$C$2:$G$9999,5,0) -> 2024/01 | P85: =VLOOKUP(J85,$C$2:$H$9999,6,0) -> 30 | Q85: =VLOOKUP(J85,'구매현황_2301-2603'!$E$2:$I$1312,5,0) -> #N/A | R85: =VLOOKUP(Q85,리드타임!$B$3:$D$10,3,0) -> #N/A | S85: =IFERROR(N85/20*R85,N85/20*90) -> 13.5
A86: 85 | B86: 2024/01 | C86: 14-K-851 | D86: OJC-A1-SC/SC-SM-3-PC/PC-SP | E86: K9088996_포앤티 | F86: 3500 | G86: =INDEX($B$2:$B$9999,MATCH(_xlfn.MAXIFS($F$2:$F$9999,$C$2:$C$9999,C86),$F$1:$F$9999,0)) -> 2025/12 | H86: =_xlfn.MAXIFS(F:F,C:C,C86,G:G,G86) -> 7100 | J86: 14-C-557 | K86: Optical Cable Parts,LC/PC-LC/PC-Single mode-35m-2Core | L86: 657A2 , LSZH , LC DUPLEX KIT(CLIP), 0MM/ 300MM | M86: 40 | N86: =+M86/20 -> 2 | O86: =VLOOKUP(J86,$C$2:$G$9999,5,0) -> 2024/01 | P86: =VLOOKUP(J86,$C$2:$H$9999,6,0) -> 20 | Q86: =VLOOKUP(J86,'구매현황_2301-2603'!$E$2:$I$1312,5,0) -> #N/A | R86: =VLOOKUP(Q86,리드타임!$B$3:$D$10,3,0) -> #N/A | S86: =IFERROR(N86/20*R86,N86/20*90) -> 9
...

Sheet 재고현황
A2: 품목코드 | B2: 품목명 | C2: 규격명 | D2: 재고수량 | E2: 021_의왕-물류 | F2: 의왕-검수대기 | H2: 46171
A3: 14-A-002 | B3: 어댑터 SC/PC-SP (ADAPTER SC/PC-SP) | C3: K9076856 | D3: 256 | E3: 256 | F3: 0
A4: 14-A-002N | B4: ADAPTER(OFA-SC/PC) | C4: NO LOGO | D4: 823 | E4: 823 | F4: 0
A5: 14-A-003 | B5: ADAPTER(OFA-SC/PC)-RED | C5: K9119065 | D5: 18 | E5: 18 | F5: 0
A6: 14-A-004 | B6: ADAPTER(OFA-SC/PC)-DUPLEX | D6: 7 | E6: 7 | F6: 0
A7: 14-A-005 | B7: ADAPTER(OFA-LC/PC)-DUPLEX | D7: 3750 | E7: 3750 | F7: 0
A8: 14-A-005C | B8: ADAPTER(OFA-LC)-DUPLEX,CLEAR | C8: COLOR : CLEAR (PC,APC 공용) | D8: 1 | E8: 1 | F8: 0
A9: 14-A-006 | B9: ADAPTER(OFA-FC/PC) | D9: 6540 | E9: 6540 | F9: 0
A10: 14-A-006B | B10: ADAPTER(OFA-FC/PC) | C10: BIG D, BRONZE SLEEVE | D10: 1034 | E10: 1034 | F10: 0
A11: 14-A-007 | B11: ADAPTER(OFA-SC/APC) | D11: 176 | E11: 176 | F11: 0
A12: 14-A-008 | B12: ADAPTER(OFA-FC/APC) | D12: 3824 | E12: 3824 | F12: 0
A13: 14-A-009 | B13: ADAPTER(OFA-FC/SC) | D13: 394 | E13: 394 | F13: 0
A14: 14-A-012 | B14: ADAPTER(OFA-LC/APC)-DUPLEX | D14: 2062 | E14: 2062 | F14: 0
A15: 14-C-056 | B15: DROP-CABLE(SC/PC) | C15: 40M | D15: 82 | E15: 82 | F15: 0
A16: 14-C-107 | B16: DROP-CABLE(LC/PC-SC/PC) | C16: 10M | D16: 19 | E16: 19 | F16: 0
A17: 14-C-134 | B17: DROP-CABLE(LC/PC) | C17: 15M | D17: 10 | E17: 10 | F17: 0
A18: 14-C-408 | B18: Optical Cable Parts,LC/PC-LC/PC-Single mode-50m-2Core | C18: 657A2 , LSZH , LC DUPLEX KIT(CLIP), 150MM/ 500MM | D18: 30 | E18: 30 | F18: 0
A19: 14-C-417 | B19: Optical Cable Parts,LC/PC-LC/PC-Single mode-2m-2Core | C19: 657A2 , LSZH , LC DUPLEX KIT(CLIP), 95MM/ 500MM | D19: 110 | E19: 110 | F19: 0
A20: 14-C-441 | B20: Optical Cable Parts,LC/PC-LC/PC-Single mode-15m-2Core | C20: 657A2 , LSZH , LC DUPLEX KIT(CLIP), 95MM/ 500MM | D20: 45 | E20: 45 | F20: 0
A21: 14-C-442 | B21: Optical Cable Parts,LC/PC-LC/PC-Single mode-20m-2Core | C21: 657A2 , LSZH , LC DUPLEX KIT(CLIP), 95MM/ 500MM | D21: 1192 | E21: 1192 | F21: 0
A22: 14-C-443 | B22: Optical Cable Parts,LC/PC-LC/PC-Single mode-25m-2Core | C22: 657A2 , LSZH , LC DUPLEX KIT(CLIP), 95MM/ 500MM | D22: 216 | E22: 216 | F22: 0
A23: 14-C-458 | B23: Optical Cable Parts,LC/PC-LC/PC-Single mode-70m-2Core | C23: 657A2 , LSZH , LC DUPLEX KIT(CLIP),95MM/ 500MM | D23: 39 | E23: 39 | F23: 0
A24: 14-C-467 | B24: DROP-CABLE(LC/PC-SC/PC) | C24: 3M | D24: 10 | E24: 10 | F24: 0
A25: 14-C-495 | B25: Optical Cable Parts,LC/PC-LC/PC-Single mode-80m-2Core | C25: 657A2 , LSZH , LC DUPLEX KIT(CLIP),95MM/ 500MM | D25: 33 | E25: 33 | F25: 0
A26: 14-C-514 | B26: Optical Cable Parts,LC/PC-LC/PC-Single mode-10m-1Core | C26: 657A2 , LSZH , LC DUPLEX KIT(CLIP), 300MM/300MM | D26: 50 | E26: 50 | F26: 0
